<?xml version="1.0"?>
<robot name="room602-kitchen"
       xmlns:xi="http://www.w3.org/2001/XInclude"
       xmlns:gazebo="http://playerstage.sourceforge.net/gazebo/xmlschema/#gz"
       xmlns:model="http://playerstage.sourceforge.net/gazebo/xmlschema/#model"
       xmlns:sensor="http://playerstage.sourceforge.net/gazebo/xmlschema/#sensor"
       xmlns:body="http://playerstage.sourceforge.net/gazebo/xmlschema/#body"
       xmlns:geom="http://playerstage.sourceforge.net/gazebo/xmlschema/#geom"
       xmlns:joint="http://playerstage.sourceforge.net/gazebo/xmlschema/#joint"
       xmlns:interface="http://playerstage.sourceforge.net/gazebo/xmlschema/#interface"
       xmlns:rendering="http://playerstage.sourceforge.net/gazebo/xmlschema/#rendering"
       xmlns:renderable="http://playerstage.sourceforge.net/gazebo/xmlschema/#renderable"
       xmlns:controller="http://playerstage.sourceforge.net/gazebo/xmlschema/#controller"
       xmlns:physics="http://playerstage.sourceforge.net/gazebo/xmlschema/#physics">
  <gazebo>
    <static>false</static>
  </gazebo>
  <link name="ROOT_link">
    <visual>
      <origin xyz="0 0 0" rpy="0 -0 0"/>
      <geometry>
        <mesh filename="model://room602-kitchen/meshes/ROOT_link_mesh.dae" scale="1 1 1" />
      </geometry>
    </visual>
    <collision>
      <origin xyz="0 0 0" rpy="0 -0 0"/>
      <geometry>
        <mesh filename="model://room602-kitchen/meshes/ROOT_link_mesh.dae" scale="1 1 1" />
      </geometry>
    </collision>
    <inertial>
      <mass value="0.001" />
      <origin xyz="0 0 0" rpy="0 -0 0"/>
      <inertia ixx="1e-09" ixy="0" ixz="0" iyy="1e-09" iyz="0" izz="1e-09"/>
    </inertial>
  </link>
  <gazebo reference="ROOT_link">
    <mu1>0.9</mu1>
    <mu2>0.9</mu2>
  </gazebo>
  <link name="ROOM602-KITCHEN-BODYSET16_link">
    <visual>
      <origin xyz="0.34 -0.485 0.73" rpy="0 -0 0"/>
      <geometry>
        <mesh filename="model://room602-kitchen/meshes/ROOM602-KITCHEN-BODYSET16_link_mesh.dae" scale="1 1 1" />
      </geometry>
    </visual>
    <collision>
      <origin xyz="0.34 -0.485 0.73" rpy="0 -0 0"/>
      <geometry>
        <mesh filename="model://room602-kitchen/meshes/ROOM602-KITCHEN-BODYSET16_link_mesh.dae" scale="1 1 1" />
      </geometry>
    </collision>
    <inertial>
      <mass value="0.001" />
      <origin xyz="0 0 0" rpy="0 -0 0"/>
      <inertia ixx="1e-09" ixy="0" ixz="0" iyy="1e-09" iyz="0" izz="1e-09"/>
    </inertial>
  </link>
  <gazebo reference="ROOM602-KITCHEN-BODYSET16_link">
    <mu1>0.9</mu1>
    <mu2>0.9</mu2>
  </gazebo>
  <link name="ROOM602-KITCHEN-BODYSET17_link">
    <visual>
      <origin xyz="0.005 0 0" rpy="1.5708 1.5708 -1.5708"/>
      <geometry>
        <mesh filename="model://room602-kitchen/meshes/ROOM602-KITCHEN-BODYSET17_link_mesh.dae" scale="1 1 1" />
      </geometry>
    </visual>
    <collision>
      <origin xyz="0.005 0 0" rpy="1.5708 1.5708 -1.5708"/>
      <geometry>
        <mesh filename="model://room602-kitchen/meshes/ROOM602-KITCHEN-BODYSET17_link_mesh.dae" scale="1 1 1" />
      </geometry>
    </collision>
    <inertial>
      <mass value="0.001" />
      <origin xyz="0 0 0" rpy="0 -0 0"/>
      <inertia ixx="1e-09" ixy="1.30938e-41" ixz="0" iyy="1e-09" iyz="-4.59177e-41" izz="1e-09"/>
    </inertial>
  </link>
  <gazebo reference="ROOM602-KITCHEN-BODYSET17_link">
    <mu1>0.9</mu1>
    <mu2>0.9</mu2>
  </gazebo>
  <link name="ROOM602-KITCHEN-BODYSET14_link">
    <visual>
      <origin xyz="0.34 -0.55 0.75" rpy="0 -0 0"/>
      <geometry>
        <mesh filename="model://room602-kitchen/meshes/ROOM602-KITCHEN-BODYSET14_link_mesh.dae" scale="1 1 1" />
      </geometry>
    </visual>
    <collision>
      <origin xyz="0.34 -0.55 0.75" rpy="0 -0 0"/>
      <geometry>
        <mesh filename="model://room602-kitchen/meshes/ROOM602-KITCHEN-BODYSET14_link_mesh.dae" scale="1 1 1" />
      </geometry>
    </collision>
    <inertial>
      <mass value="0.001" />
      <origin xyz="0 0 0" rpy="0 -0 0"/>
      <inertia ixx="1e-09" ixy="0" ixz="0" iyy="1e-09" iyz="0" izz="1e-09"/>
    </inertial>
  </link>
  <gazebo reference="ROOM602-KITCHEN-BODYSET14_link">
    <mu1>0.9</mu1>
    <mu2>0.9</mu2>
  </gazebo>
  <link name="ROOM602-KITCHEN-BODYSET15_link">
    <visual>
      <origin xyz="0.005 0 0" rpy="1.5708 1.5708 -1.5708"/>
      <geometry>
        <mesh filename="model://room602-kitchen/meshes/ROOM602-KITCHEN-BODYSET15_link_mesh.dae" scale="1 1 1" />
      </geometry>
    </visual>
    <collision>
      <origin xyz="0.005 0 0" rpy="1.5708 1.5708 -1.5708"/>
      <geometry>
        <mesh filename="model://room602-kitchen/meshes/ROOM602-KITCHEN-BODYSET15_link_mesh.dae" scale="1 1 1" />
      </geometry>
    </collision>
    <inertial>
      <mass value="0.001" />
      <origin xyz="0 0 0" rpy="0 -0 0"/>
      <inertia ixx="1e-09" ixy="1.30938e-41" ixz="0" iyy="1e-09" iyz="-4.59177e-41" izz="1e-09"/>
    </inertial>
  </link>
  <gazebo reference="ROOM602-KITCHEN-BODYSET15_link">
    <mu1>0.9</mu1>
    <mu2>0.9</mu2>
  </gazebo>
  <link name="ROOM602-KITCHEN-BODYSET12_link">
    <visual>
      <origin xyz="0.34 -0.615 0.73" rpy="0 -0 0"/>
      <geometry>
        <mesh filename="model://room602-kitchen/meshes/ROOM602-KITCHEN-BODYSET12_link_mesh.dae" scale="1 1 1" />
      </geometry>
    </visual>
    <collision>
      <origin xyz="0.34 -0.615 0.73" rpy="0 -0 0"/>
      <geometry>
        <mesh filename="model://room602-kitchen/meshes/ROOM602-KITCHEN-BODYSET12_link_mesh.dae" scale="1 1 1" />
      </geometry>
    </collision>
    <inertial>
      <mass value="0.001" />
      <origin xyz="0 0 0" rpy="0 -0 0"/>
      <inertia ixx="1e-09" ixy="0" ixz="0" iyy="1e-09" iyz="0" izz="1e-09"/>
    </inertial>
  </link>
  <gazebo reference="ROOM602-KITCHEN-BODYSET12_link">
    <mu1>0.9</mu1>
    <mu2>0.9</mu2>
  </gazebo>
  <link name="ROOM602-KITCHEN-BODYSET13_link">
    <visual>
      <origin xyz="0.005 0 0" rpy="1.5708 1.5708 -1.5708"/>
      <geometry>
        <mesh filename="model://room602-kitchen/meshes/ROOM602-KITCHEN-BODYSET13_link_mesh.dae" scale="1 1 1" />
      </geometry>
    </visual>
    <collision>
      <origin xyz="0.005 0 0" rpy="1.5708 1.5708 -1.5708"/>
      <geometry>
        <mesh filename="model://room602-kitchen/meshes/ROOM602-KITCHEN-BODYSET13_link_mesh.dae" scale="1 1 1" />
      </geometry>
    </collision>
    <inertial>
      <mass value="0.001" />
      <origin xyz="0 0 0" rpy="0 -0 0"/>
      <inertia ixx="1e-09" ixy="1.30938e-41" ixz="0" iyy="1e-09" iyz="-4.59177e-41" izz="1e-09"/>
    </inertial>
  </link>
  <gazebo reference="ROOM602-KITCHEN-BODYSET13_link">
    <mu1>0.9</mu1>
    <mu2>0.9</mu2>
  </gazebo>
  <link name="ROOM602-KITCHEN-BODYSET7_link">
    <visual>
      <origin xyz="0.025 0.001 0.405" rpy="0 -0 0"/>
      <geometry>
        <mesh filename="model://room602-kitchen/meshes/ROOM602-KITCHEN-BODYSET7_link_mesh.dae" scale="1 1 1" />
      </geometry>
    </visual>
    <collision>
      <origin xyz="0.025 0.001 0.405" rpy="0 -0 0"/>
      <geometry>
        <mesh filename="model://room602-kitchen/meshes/ROOM602-KITCHEN-BODYSET7_link_mesh.dae" scale="1 1 1" />
      </geometry>
    </collision>
    <inertial>
      <mass value="0.001" />
      <origin xyz="0 0 0" rpy="0 -0 0"/>
      <inertia ixx="1e-09" ixy="0" ixz="0" iyy="1e-09" iyz="0" izz="1e-09"/>
    </inertial>
  </link>
  <gazebo reference="ROOM602-KITCHEN-BODYSET7_link">
    <mu1>0.9</mu1>
    <mu2>0.9</mu2>
  </gazebo>
  <link name="ROOM602-KITCHEN-BODYSET10_link">
    <visual>
      <origin xyz="0.025 0.006 0.685" rpy="0 -0 0"/>
      <geometry>
        <mesh filename="model://room602-kitchen/meshes/ROOM602-KITCHEN-BODYSET10_link_mesh.dae" scale="1 1 1" />
      </geometry>
    </visual>
    <collision>
      <origin xyz="0.025 0.006 0.685" rpy="0 -0 0"/>
      <geometry>
        <mesh filename="model://room602-kitchen/meshes/ROOM602-KITCHEN-BODYSET10_link_mesh.dae" scale="1 1 1" />
      </geometry>
    </collision>
    <inertial>
      <mass value="0.001" />
      <origin xyz="0 0 0" rpy="0 -0 0"/>
      <inertia ixx="1e-09" ixy="0" ixz="0" iyy="1e-09" iyz="0" izz="1e-09"/>
    </inertial>
  </link>
  <gazebo reference="ROOM602-KITCHEN-BODYSET10_link">
    <mu1>0.9</mu1>
    <mu2>0.9</mu2>
  </gazebo>
  <link name="ROOM602-KITCHEN-BODYSET11_link">
    <visual>
      <origin xyz="0.025 -0.805 0.66" rpy="0 -0 0"/>
      <geometry>
        <mesh filename="model://room602-kitchen/meshes/ROOM602-KITCHEN-BODYSET11_link_mesh.dae" scale="1 1 1" />
      </geometry>
    </visual>
    <collision>
      <origin xyz="0.025 -0.805 0.66" rpy="0 -0 0"/>
      <geometry>
        <mesh filename="model://room602-kitchen/meshes/ROOM602-KITCHEN-BODYSET11_link_mesh.dae" scale="1 1 1" />
      </geometry>
    </collision>
    <inertial>
      <mass value="0.001" />
      <origin xyz="0 0 0" rpy="0 -0 0"/>
      <inertia ixx="1e-09" ixy="0" ixz="0" iyy="1e-09" iyz="0" izz="1e-09"/>
    </inertial>
  </link>
  <gazebo reference="ROOM602-KITCHEN-BODYSET11_link">
    <mu1>0.9</mu1>
    <mu2>0.9</mu2>
  </gazebo>
  <link name="ROOM602-KITCHEN-BODYSET2_link">
    <visual>
      <origin xyz="0.025 -0.524 0.137" rpy="0 -0 0"/>
      <geometry>
        <mesh filename="model://room602-kitchen/meshes/ROOM602-KITCHEN-BODYSET2_link_mesh.dae" scale="1 1 1" />
      </geometry>
    </visual>
    <collision>
      <origin xyz="0.025 -0.524 0.137" rpy="0 -0 0"/>
      <geometry>
        <mesh filename="model://room602-kitchen/meshes/ROOM602-KITCHEN-BODYSET2_link_mesh.dae" scale="1 1 1" />
      </geometry>
    </collision>
    <inertial>
      <mass value="0.001" />
      <origin xyz="0 0 0" rpy="0 -0 0"/>
      <inertia ixx="1e-09" ixy="0" ixz="0" iyy="1e-09" iyz="0" izz="1e-09"/>
    </inertial>
  </link>
  <gazebo reference="ROOM602-KITCHEN-BODYSET2_link">
    <mu1>0.9</mu1>
    <mu2>0.9</mu2>
  </gazebo>
  <link name="ROOM602-KITCHEN-BODYSET6_link">
    <visual>
      <origin xyz="0.025 -0.601 0.405" rpy="0 -0 0"/>
      <geometry>
        <mesh filename="model://room602-kitchen/meshes/ROOM602-KITCHEN-BODYSET6_link_mesh.dae" scale="1 1 1" />
      </geometry>
    </visual>
    <collision>
      <origin xyz="0.025 -0.601 0.405" rpy="0 -0 0"/>
      <geometry>
        <mesh filename="model://room602-kitchen/meshes/ROOM602-KITCHEN-BODYSET6_link_mesh.dae" scale="1 1 1" />
      </geometry>
    </collision>
    <inertial>
      <mass value="0.001" />
      <origin xyz="0 0 0" rpy="0 -0 0"/>
      <inertia ixx="1e-09" ixy="0" ixz="0" iyy="1e-09" iyz="0" izz="1e-09"/>
    </inertial>
  </link>
  <gazebo reference="ROOM602-KITCHEN-BODYSET6_link">
    <mu1>0.9</mu1>
    <mu2>0.9</mu2>
  </gazebo>
  <link name="ROOM602-KITCHEN-BODYSET4_link">
    <visual>
      <origin xyz="0.315 -1.123 0.06" rpy="0 -0 0"/>
      <geometry>
        <mesh filename="model://room602-kitchen/meshes/ROOM602-KITCHEN-BODYSET4_link_mesh.dae" scale="1 1 1" />
      </geometry>
    </visual>
    <collision>
      <origin xyz="0.315 -1.123 0.06" rpy="0 -0 0"/>
      <geometry>
        <mesh filename="model://room602-kitchen/meshes/ROOM602-KITCHEN-BODYSET4_link_mesh.dae" scale="1 1 1" />
      </geometry>
    </collision>
    <inertial>
      <mass value="0.001" />
      <origin xyz="0 0 0" rpy="0 -0 0"/>
      <inertia ixx="1e-09" ixy="0" ixz="0" iyy="1e-09" iyz="0" izz="1e-09"/>
    </inertial>
  </link>
  <gazebo reference="ROOM602-KITCHEN-BODYSET4_link">
    <mu1>0.9</mu1>
    <mu2>0.9</mu2>
  </gazebo>
  <link name="ROOM602-KITCHEN-BODYSET9_link">
    <visual>
      <origin xyz="0.025 -0.346 0.7" rpy="0 -0 0"/>
      <geometry>
        <mesh filename="model://room602-kitchen/meshes/ROOM602-KITCHEN-BODYSET9_link_mesh.dae" scale="1 1 1" />
      </geometry>
    </visual>
    <collision>
      <origin xyz="0.025 -0.346 0.7" rpy="0 -0 0"/>
      <geometry>
        <mesh filename="model://room602-kitchen/meshes/ROOM602-KITCHEN-BODYSET9_link_mesh.dae" scale="1 1 1" />
      </geometry>
    </collision>
    <inertial>
      <mass value="0.001" />
      <origin xyz="0 0 0" rpy="0 -0 0"/>
      <inertia ixx="1e-09" ixy="0" ixz="0" iyy="1e-09" iyz="0" izz="1e-09"/>
    </inertial>
  </link>
  <gazebo reference="ROOM602-KITCHEN-BODYSET9_link">
    <mu1>0.9</mu1>
    <mu2>0.9</mu2>
  </gazebo>
  <link name="ROOM602-KITCHEN-BODYSET3_link">
    <visual>
      <origin xyz="0.025 0.451 0.137" rpy="0 -0 0"/>
      <geometry>
        <mesh filename="model://room602-kitchen/meshes/ROOM602-KITCHEN-BODYSET3_link_mesh.dae" scale="1 1 1" />
      </geometry>
    </visual>
    <collision>
      <origin xyz="0.025 0.451 0.137" rpy="0 -0 0"/>
      <geometry>
        <mesh filename="model://room602-kitchen/meshes/ROOM602-KITCHEN-BODYSET3_link_mesh.dae" scale="1 1 1" />
      </geometry>
    </collision>
    <inertial>
      <mass value="0.001" />
      <origin xyz="0 0 0" rpy="0 -0 0"/>
      <inertia ixx="1e-09" ixy="0" ixz="0" iyy="1e-09" iyz="0" izz="1e-09"/>
    </inertial>
  </link>
  <gazebo reference="ROOM602-KITCHEN-BODYSET3_link">
    <mu1>0.9</mu1>
    <mu2>0.9</mu2>
  </gazebo>
  <link name="ROOM602-KITCHEN-BODYSET8_link">
    <visual>
      <origin xyz="0.025 0.603 0.405" rpy="0 -0 0"/>
      <geometry>
        <mesh filename="model://room602-kitchen/meshes/ROOM602-KITCHEN-BODYSET8_link_mesh.dae" scale="1 1 1" />
      </geometry>
    </visual>
    <collision>
      <origin xyz="0.025 0.603 0.405" rpy="0 -0 0"/>
      <geometry>
        <mesh filename="model://room602-kitchen/meshes/ROOM602-KITCHEN-BODYSET8_link_mesh.dae" scale="1 1 1" />
      </geometry>
    </collision>
    <inertial>
      <mass value="0.001" />
      <origin xyz="0 0 0" rpy="0 -0 0"/>
      <inertia ixx="1e-09" ixy="0" ixz="0" iyy="1e-09" iyz="0" izz="1e-09"/>
    </inertial>
  </link>
  <gazebo reference="ROOM602-KITCHEN-BODYSET8_link">
    <mu1>0.9</mu1>
    <mu2>0.9</mu2>
  </gazebo>
  <link name="ROOM602-KITCHEN-BODYSET5_link">
    <visual>
      <origin xyz="0.315 1.123 0.06" rpy="0 -0 0"/>
      <geometry>
        <mesh filename="model://room602-kitchen/meshes/ROOM602-KITCHEN-BODYSET5_link_mesh.dae" scale="1 1 1" />
      </geometry>
    </visual>
    <collision>
      <origin xyz="0.315 1.123 0.06" rpy="0 -0 0"/>
      <geometry>
        <mesh filename="model://room602-kitchen/meshes/ROOM602-KITCHEN-BODYSET5_link_mesh.dae" scale="1 1 1" />
      </geometry>
    </collision>
    <inertial>
      <mass value="0.001" />
      <origin xyz="0 0 0" rpy="0 -0 0"/>
      <inertia ixx="1e-09" ixy="0" ixz="0" iyy="1e-09" iyz="0" izz="1e-09"/>
    </inertial>
  </link>
  <gazebo reference="ROOM602-KITCHEN-BODYSET5_link">
    <mu1>0.9</mu1>
    <mu2>0.9</mu2>
  </gazebo>
  <link name="TAP-HANDLE-BODY_link">
    <visual>
      <origin xyz="-0.0826664 1.11267 1.00531" rpy="1.26878e-07 -0.488693 -0.785399"/>
      <geometry>
        <mesh filename="model://room602-kitchen/meshes/TAP-HANDLE-BODY_link_mesh.dae" scale="1 1 1" />
      </geometry>
    </visual>
    <collision>
      <origin xyz="-0.0826664 1.11267 1.00531" rpy="1.26878e-07 -0.488693 -0.785399"/>
      <geometry>
        <mesh filename="model://room602-kitchen/meshes/TAP-HANDLE-BODY_link_mesh.dae" scale="1 1 1" />
      </geometry>
    </collision>
    <inertial>
      <mass value="0.001" />
      <origin xyz="0 0 0" rpy="0 -0 0"/>
      <inertia ixx="1e-09" ixy="-1.40233e-32" ixz="0" iyy="1e-09" iyz="-9.86076e-32" izz="1e-09"/>
    </inertial>
  </link>
  <gazebo reference="TAP-HANDLE-BODY_link">
    <mu1>0.9</mu1>
    <mu2>0.9</mu2>
  </gazebo>
  <link name="TAP-TUBE_link">
    <visual>
      <origin xyz="-0.09 1.12 0.84" rpy="0 0 -1.5708"/>
      <geometry>
        <mesh filename="model://room602-kitchen/meshes/TAP-TUBE_link_mesh.dae" scale="1 1 1" />
      </geometry>
    </visual>
    <collision>
      <origin xyz="-0.09 1.12 0.84" rpy="0 0 -1.5708"/>
      <geometry>
        <mesh filename="model://room602-kitchen/meshes/TAP-TUBE_link_mesh.dae" scale="1 1 1" />
      </geometry>
    </collision>
    <inertial>
      <mass value="0.001" />
      <origin xyz="0 0 0" rpy="0 -0 0"/>
      <inertia ixx="1e-09" ixy="-7.4988e-42" ixz="0" iyy="1e-09" iyz="0" izz="1e-09"/>
    </inertial>
  </link>
  <gazebo reference="TAP-TUBE_link">
    <mu1>0.9</mu1>
    <mu2>0.9</mu2>
  </gazebo>
  <joint name="BUTTON0-BODY-JOINT-1" type="prismatic">
    <parent link="ROOT_link"/>
    <child  link="ROOM602-KITCHEN-BODYSET16_link"/>
    <origin xyz="0.34 -0.485 0.73" rpy="0 -0 0 "/>
    <axis   xyz="1 0 0"/>
    <limit lower="-0.09" upper="0.09" effort="100" velocity="0.01" />
    <dynamics damping="0.2" friction="0" />
  </joint>
  <transmission type="pr2_mechanism_model/SimpleTransmission" name="BUTTON0-BODY-JOINT-1_trans" >
    <actuator name="BUTTON0-BODY-JOINT-1_motor" />
    <joint name="BUTTON0-BODY-JOINT-1" />
    <mechanicalReduction>1</mechanicalReduction>
  </transmission>
  <gazebo reference="BUTTON0-BODY-JOINT-1">
    <cfmDamping>0.4</cfmDamping>
  </gazebo>
  <joint name="BUTTON0-BODY-JOINT-2" type="revolute">
    <parent link="ROOM602-KITCHEN-BODYSET16_link"/>
    <child  link="ROOM602-KITCHEN-BODYSET17_link"/>
    <origin xyz="0.005 0 0" rpy="1.5708 1.5708 -1.5708 "/>
    <axis   xyz="-1 -1.47826e-16 0"/>
    <limit lower="-1.5708" upper="1.5708" effort="100" velocity="0.5" />
    <dynamics damping="0.2" friction="0" />
  </joint>
  <transmission type="pr2_mechanism_model/SimpleTransmission" name="BUTTON0-BODY-JOINT-2_trans" >
    <actuator name="BUTTON0-BODY-JOINT-2_motor" />
    <joint name="BUTTON0-BODY-JOINT-2" />
    <mechanicalReduction>1</mechanicalReduction>
  </transmission>
  <gazebo reference="BUTTON0-BODY-JOINT-2">
    <cfmDamping>0.4</cfmDamping>
  </gazebo>
  <joint name="BUTTON1-BODY-JOINT-1" type="prismatic">
    <parent link="ROOT_link"/>
    <child  link="ROOM602-KITCHEN-BODYSET14_link"/>
    <origin xyz="0.34 -0.55 0.75" rpy="0 -0 0 "/>
    <axis   xyz="1 0 0"/>
    <limit lower="-0.09" upper="0.09" effort="100" velocity="0.01" />
    <dynamics damping="0.2" friction="0" />
  </joint>
  <transmission type="pr2_mechanism_model/SimpleTransmission" name="BUTTON1-BODY-JOINT-1_trans" >
    <actuator name="BUTTON1-BODY-JOINT-1_motor" />
    <joint name="BUTTON1-BODY-JOINT-1" />
    <mechanicalReduction>1</mechanicalReduction>
  </transmission>
  <gazebo reference="BUTTON1-BODY-JOINT-1">
    <cfmDamping>0.4</cfmDamping>
  </gazebo>
  <joint name="BUTTON1-BODY-JOINT-2" type="revolute">
    <parent link="ROOM602-KITCHEN-BODYSET14_link"/>
    <child  link="ROOM602-KITCHEN-BODYSET15_link"/>
    <origin xyz="0.005 0 0" rpy="1.5708 1.5708 -1.5708 "/>
    <axis   xyz="-1 -1.47826e-16 0"/>
    <limit lower="-1.5708" upper="1.5708" effort="100" velocity="0.5" />
    <dynamics damping="0.2" friction="0" />
  </joint>
  <transmission type="pr2_mechanism_model/SimpleTransmission" name="BUTTON1-BODY-JOINT-2_trans" >
    <actuator name="BUTTON1-BODY-JOINT-2_motor" />
    <joint name="BUTTON1-BODY-JOINT-2" />
    <mechanicalReduction>1</mechanicalReduction>
  </transmission>
  <gazebo reference="BUTTON1-BODY-JOINT-2">
    <cfmDamping>0.4</cfmDamping>
  </gazebo>
  <joint name="BUTTON2-BODY-JOINT-1" type="prismatic">
    <parent link="ROOT_link"/>
    <child  link="ROOM602-KITCHEN-BODYSET12_link"/>
    <origin xyz="0.34 -0.615 0.73" rpy="0 -0 0 "/>
    <axis   xyz="1 0 0"/>
    <limit lower="-0.09" upper="0.09" effort="100" velocity="0.01" />
    <dynamics damping="0.2" friction="0" />
  </joint>
  <transmission type="pr2_mechanism_model/SimpleTransmission" name="BUTTON2-BODY-JOINT-1_trans" >
    <actuator name="BUTTON2-BODY-JOINT-1_motor" />
    <joint name="BUTTON2-BODY-JOINT-1" />
    <mechanicalReduction>1</mechanicalReduction>
  </transmission>
  <gazebo reference="BUTTON2-BODY-JOINT-1">
    <cfmDamping>0.4</cfmDamping>
  </gazebo>
  <joint name="BUTTON2-BODY-JOINT-2" type="revolute">
    <parent link="ROOM602-KITCHEN-BODYSET12_link"/>
    <child  link="ROOM602-KITCHEN-BODYSET13_link"/>
    <origin xyz="0.005 0 0" rpy="1.5708 1.5708 -1.5708 "/>
    <axis   xyz="-1 -1.47826e-16 0"/>
    <limit lower="-1.5708" upper="1.5708" effort="100" velocity="0.5" />
    <dynamics damping="0.2" friction="0" />
  </joint>
  <transmission type="pr2_mechanism_model/SimpleTransmission" name="BUTTON2-BODY-JOINT-2_trans" >
    <actuator name="BUTTON2-BODY-JOINT-2_motor" />
    <joint name="BUTTON2-BODY-JOINT-2" />
    <mechanicalReduction>1</mechanicalReduction>
  </transmission>
  <gazebo reference="BUTTON2-BODY-JOINT-2">
    <cfmDamping>0.4</cfmDamping>
  </gazebo>
  <joint name="CENTER-MIDDLE-DRAWER" type="prismatic">
    <parent link="ROOT_link"/>
    <child  link="ROOM602-KITCHEN-BODYSET7_link"/>
    <origin xyz="0.025 0.001 0.405" rpy="0 -0 0 "/>
    <axis   xyz="1 0 0"/>
    <limit lower="0" upper="0.63" effort="100" velocity="0.01" />
    <dynamics damping="0.2" friction="0" />
  </joint>
  <transmission type="pr2_mechanism_model/SimpleTransmission" name="CENTER-MIDDLE-DRAWER_trans" >
    <actuator name="CENTER-MIDDLE-DRAWER_motor" />
    <joint name="CENTER-MIDDLE-DRAWER" />
    <mechanicalReduction>1</mechanicalReduction>
  </transmission>
  <gazebo reference="CENTER-MIDDLE-DRAWER">
    <cfmDamping>0.4</cfmDamping>
  </gazebo>
  <joint name="CENTER-TOP-DRAWER" type="prismatic">
    <parent link="ROOT_link"/>
    <child  link="ROOM602-KITCHEN-BODYSET10_link"/>
    <origin xyz="0.025 0.006 0.685" rpy="0 -0 0 "/>
    <axis   xyz="1 0 0"/>
    <limit lower="0" upper="0.63" effort="100" velocity="0.01" />
    <dynamics damping="0.2" friction="0" />
  </joint>
  <transmission type="pr2_mechanism_model/SimpleTransmission" name="CENTER-TOP-DRAWER_trans" >
    <actuator name="CENTER-TOP-DRAWER_motor" />
    <joint name="CENTER-TOP-DRAWER" />
    <mechanicalReduction>1</mechanicalReduction>
  </transmission>
  <gazebo reference="CENTER-TOP-DRAWER">
    <cfmDamping>0.4</cfmDamping>
  </gazebo>
  <joint name="DRAWER" type="prismatic">
    <parent link="ROOT_link"/>
    <child  link="ROOM602-KITCHEN-BODYSET11_link"/>
    <origin xyz="0.025 -0.805 0.66" rpy="0 -0 0 "/>
    <axis   xyz="1 0 0"/>
    <limit lower="0" upper="0.63" effort="100" velocity="0.01" />
    <dynamics damping="0.2" friction="0" />
  </joint>
  <transmission type="pr2_mechanism_model/SimpleTransmission" name="DRAWER_trans" >
    <actuator name="DRAWER_motor" />
    <joint name="DRAWER" />
    <mechanicalReduction>1</mechanicalReduction>
  </transmission>
  <gazebo reference="DRAWER">
    <cfmDamping>0.4</cfmDamping>
  </gazebo>
  <joint name="LEFT-BOTTOM-DRAWER" type="prismatic">
    <parent link="ROOT_link"/>
    <child  link="ROOM602-KITCHEN-BODYSET2_link"/>
    <origin xyz="0.025 -0.524 0.137" rpy="0 -0 0 "/>
    <axis   xyz="1 0 0"/>
    <limit lower="0" upper="0.63" effort="100" velocity="0.01" />
    <dynamics damping="0.2" friction="0" />
  </joint>
  <transmission type="pr2_mechanism_model/SimpleTransmission" name="LEFT-BOTTOM-DRAWER_trans" >
    <actuator name="LEFT-BOTTOM-DRAWER_motor" />
    <joint name="LEFT-BOTTOM-DRAWER" />
    <mechanicalReduction>1</mechanicalReduction>
  </transmission>
  <gazebo reference="LEFT-BOTTOM-DRAWER">
    <cfmDamping>0.4</cfmDamping>
  </gazebo>
  <joint name="LEFT-MIDDLE-DRAWER" type="prismatic">
    <parent link="ROOT_link"/>
    <child  link="ROOM602-KITCHEN-BODYSET6_link"/>
    <origin xyz="0.025 -0.601 0.405" rpy="0 -0 0 "/>
    <axis   xyz="1 0 0"/>
    <limit lower="0" upper="0.63" effort="100" velocity="0.01" />
    <dynamics damping="0.2" friction="0" />
  </joint>
  <transmission type="pr2_mechanism_model/SimpleTransmission" name="LEFT-MIDDLE-DRAWER_trans" >
    <actuator name="LEFT-MIDDLE-DRAWER_motor" />
    <joint name="LEFT-MIDDLE-DRAWER" />
    <mechanicalReduction>1</mechanicalReduction>
  </transmission>
  <gazebo reference="LEFT-MIDDLE-DRAWER">
    <cfmDamping>0.4</cfmDamping>
  </gazebo>
  <joint name="LEFT-SIDE-DOOR" type="revolute">
    <parent link="ROOT_link"/>
    <child  link="ROOM602-KITCHEN-BODYSET4_link"/>
    <origin xyz="0.315 -1.123 0.06" rpy="0 -0 0 "/>
    <axis   xyz="0 0 -1"/>
    <limit lower="0" upper="1.5708" effort="100" velocity="0.5" />
    <dynamics damping="0.2" friction="0" />
  </joint>
  <transmission type="pr2_mechanism_model/SimpleTransmission" name="LEFT-SIDE-DOOR_trans" >
    <actuator name="LEFT-SIDE-DOOR_motor" />
    <joint name="LEFT-SIDE-DOOR" />
    <mechanicalReduction>1</mechanicalReduction>
  </transmission>
  <gazebo reference="LEFT-SIDE-DOOR">
    <cfmDamping>0.4</cfmDamping>
  </gazebo>
  <joint name="LEFT-TOP-DRAWER" type="prismatic">
    <parent link="ROOT_link"/>
    <child  link="ROOM602-KITCHEN-BODYSET9_link"/>
    <origin xyz="0.025 -0.346 0.7" rpy="0 -0 0 "/>
    <axis   xyz="1 0 0"/>
    <limit lower="0" upper="0.63" effort="100" velocity="0.01" />
    <dynamics damping="0.2" friction="0" />
  </joint>
  <transmission type="pr2_mechanism_model/SimpleTransmission" name="LEFT-TOP-DRAWER_trans" >
    <actuator name="LEFT-TOP-DRAWER_motor" />
    <joint name="LEFT-TOP-DRAWER" />
    <mechanicalReduction>1</mechanicalReduction>
  </transmission>
  <gazebo reference="LEFT-TOP-DRAWER">
    <cfmDamping>0.4</cfmDamping>
  </gazebo>
  <joint name="RIGHT-BOTTOM-DRAWER" type="prismatic">
    <parent link="ROOT_link"/>
    <child  link="ROOM602-KITCHEN-BODYSET3_link"/>
    <origin xyz="0.025 0.451 0.137" rpy="0 -0 0 "/>
    <axis   xyz="1 0 0"/>
    <limit lower="0" upper="0.63" effort="100" velocity="0.01" />
    <dynamics damping="0.2" friction="0" />
  </joint>
  <transmission type="pr2_mechanism_model/SimpleTransmission" name="RIGHT-BOTTOM-DRAWER_trans" >
    <actuator name="RIGHT-BOTTOM-DRAWER_motor" />
    <joint name="RIGHT-BOTTOM-DRAWER" />
    <mechanicalReduction>1</mechanicalReduction>
  </transmission>
  <gazebo reference="RIGHT-BOTTOM-DRAWER">
    <cfmDamping>0.4</cfmDamping>
  </gazebo>
  <joint name="RIGHT-MIDDLE-DRAWER" type="prismatic">
    <parent link="ROOT_link"/>
    <child  link="ROOM602-KITCHEN-BODYSET8_link"/>
    <origin xyz="0.025 0.603 0.405" rpy="0 -0 0 "/>
    <axis   xyz="1 0 0"/>
    <limit lower="0" upper="0.63" effort="100" velocity="0.01" />
    <dynamics damping="0.2" friction="0" />
  </joint>
  <transmission type="pr2_mechanism_model/SimpleTransmission" name="RIGHT-MIDDLE-DRAWER_trans" >
    <actuator name="RIGHT-MIDDLE-DRAWER_motor" />
    <joint name="RIGHT-MIDDLE-DRAWER" />
    <mechanicalReduction>1</mechanicalReduction>
  </transmission>
  <gazebo reference="RIGHT-MIDDLE-DRAWER">
    <cfmDamping>0.4</cfmDamping>
  </gazebo>
  <joint name="RIGHT-SIDE-DOOR" type="revolute">
    <parent link="ROOT_link"/>
    <child  link="ROOM602-KITCHEN-BODYSET5_link"/>
    <origin xyz="0.315 1.123 0.06" rpy="0 -0 0 "/>
    <axis   xyz="0 0 1"/>
    <limit lower="0" upper="1.5708" effort="100" velocity="0.5" />
    <dynamics damping="0.2" friction="0" />
  </joint>
  <transmission type="pr2_mechanism_model/SimpleTransmission" name="RIGHT-SIDE-DOOR_trans" >
    <actuator name="RIGHT-SIDE-DOOR_motor" />
    <joint name="RIGHT-SIDE-DOOR" />
    <mechanicalReduction>1</mechanicalReduction>
  </transmission>
  <gazebo reference="RIGHT-SIDE-DOOR">
    <cfmDamping>0.4</cfmDamping>
  </gazebo>
  <joint name="TAP-HANDLE-JOINT" type="revolute">
    <parent link="ROOT_link"/>
    <child  link="TAP-HANDLE-BODY_link"/>
    <origin xyz="-0.0826664 1.11267 1.00531" rpy="1.26878e-07 -0.488693 -0.785399 "/>
    <axis   xyz="0.707107 0.707106 1.12027e-07"/>
    <limit lower="-1.5708" upper="1.5708" effort="100" velocity="0.5" />
    <dynamics damping="0.2" friction="0" />
  </joint>
  <transmission type="pr2_mechanism_model/SimpleTransmission" name="TAP-HANDLE-JOINT_trans" >
    <actuator name="TAP-HANDLE-JOINT_motor" />
    <joint name="TAP-HANDLE-JOINT" />
    <mechanicalReduction>1</mechanicalReduction>
  </transmission>
  <gazebo reference="TAP-HANDLE-JOINT">
    <cfmDamping>0.4</cfmDamping>
  </gazebo>
  <joint name="TAP-TUBE-JOINT" type="revolute">
    <parent link="ROOT_link"/>
    <child  link="TAP-TUBE_link"/>
    <origin xyz="-0.09 1.12 0.84" rpy="0 0 -1.5708 "/>
    <axis   xyz="0 0 1"/>
    <limit lower="-1.5708" upper="1.5708" effort="100" velocity="0.5" />
    <dynamics damping="0.2" friction="0" />
  </joint>
  <transmission type="pr2_mechanism_model/SimpleTransmission" name="TAP-TUBE-JOINT_trans" >
    <actuator name="TAP-TUBE-JOINT_motor" />
    <joint name="TAP-TUBE-JOINT" />
    <mechanicalReduction>1</mechanicalReduction>
  </transmission>
  <gazebo reference="TAP-TUBE-JOINT">
    <cfmDamping>0.4</cfmDamping>
  </gazebo>
</robot>
