<?xml version="1.0"?>
<robot name="naiki-6door-closet"
       xmlns:xi="http://www.w3.org/2001/XInclude"
       xmlns:gazebo="http://playerstage.sourceforge.net/gazebo/xmlschema/#gz"
       xmlns:model="http://playerstage.sourceforge.net/gazebo/xmlschema/#model"
       xmlns:sensor="http://playerstage.sourceforge.net/gazebo/xmlschema/#sensor"
       xmlns:body="http://playerstage.sourceforge.net/gazebo/xmlschema/#body"
       xmlns:geom="http://playerstage.sourceforge.net/gazebo/xmlschema/#geom"
       xmlns:joint="http://playerstage.sourceforge.net/gazebo/xmlschema/#joint"
       xmlns:interface="http://playerstage.sourceforge.net/gazebo/xmlschema/#interface"
       xmlns:rendering="http://playerstage.sourceforge.net/gazebo/xmlschema/#rendering"
       xmlns:renderable="http://playerstage.sourceforge.net/gazebo/xmlschema/#renderable"
       xmlns:controller="http://playerstage.sourceforge.net/gazebo/xmlschema/#controller"
       xmlns:physics="http://playerstage.sourceforge.net/gazebo/xmlschema/#physics">
  <gazebo>
    <static>false</static>
  </gazebo>
  <link name="ROOT_link">
    <visual>
      <origin xyz="0 0 0" rpy="0 -0 0"/>
      <geometry>
        <mesh filename="model://naiki-6door-closet/meshes/ROOT_link_mesh.dae" scale="1 1 1" />
      </geometry>
    </visual>
    <collision>
      <origin xyz="0 0 0" rpy="0 -0 0"/>
      <geometry>
        <mesh filename="model://naiki-6door-closet/meshes/ROOT_link_mesh.dae" scale="1 1 1" />
      </geometry>
    </collision>
    <inertial>
      <mass value="0.001" />
      <origin xyz="0 0 0" rpy="0 -0 0"/>
      <inertia ixx="1e-09" ixy="0" ixz="0" iyy="1e-09" iyz="0" izz="1e-09"/>
    </inertial>
  </link>
  <gazebo reference="ROOT_link">
    <mu1>0.9</mu1>
    <mu2>0.9</mu2>
  </gazebo>
  <link name="NAIKI-6DOOR-CLOSET-BODYSET7_link">
    <visual>
      <origin xyz="0.2555 -0.148667 0.93" rpy="0 -0 0"/>
      <geometry>
        <mesh filename="model://naiki-6door-closet/meshes/NAIKI-6DOOR-CLOSET-BODYSET7_link_mesh.dae" scale="1 1 1" />
      </geometry>
    </visual>
    <collision>
      <origin xyz="0.2555 -0.148667 0.93" rpy="0 -0 0"/>
      <geometry>
        <mesh filename="model://naiki-6door-closet/meshes/NAIKI-6DOOR-CLOSET-BODYSET7_link_mesh.dae" scale="1 1 1" />
      </geometry>
    </collision>
    <inertial>
      <mass value="0.001" />
      <origin xyz="0 0 0" rpy="0 -0 0"/>
      <inertia ixx="1e-09" ixy="0" ixz="0" iyy="1e-09" iyz="0" izz="1e-09"/>
    </inertial>
  </link>
  <gazebo reference="NAIKI-6DOOR-CLOSET-BODYSET7_link">
    <mu1>0.9</mu1>
    <mu2>0.9</mu2>
  </gazebo>
  <link name="NAIKI-6DOOR-CLOSET-BODYSET6_link">
    <visual>
      <origin xyz="0.2555 0.144667 0.93" rpy="0 -0 0"/>
      <geometry>
        <mesh filename="model://naiki-6door-closet/meshes/NAIKI-6DOOR-CLOSET-BODYSET6_link_mesh.dae" scale="1 1 1" />
      </geometry>
    </visual>
    <collision>
      <origin xyz="0.2555 0.144667 0.93" rpy="0 -0 0"/>
      <geometry>
        <mesh filename="model://naiki-6door-closet/meshes/NAIKI-6DOOR-CLOSET-BODYSET6_link_mesh.dae" scale="1 1 1" />
      </geometry>
    </collision>
    <inertial>
      <mass value="0.001" />
      <origin xyz="0 0 0" rpy="0 -0 0"/>
      <inertia ixx="1e-09" ixy="0" ixz="0" iyy="1e-09" iyz="0" izz="1e-09"/>
    </inertial>
  </link>
  <gazebo reference="NAIKI-6DOOR-CLOSET-BODYSET6_link">
    <mu1>0.9</mu1>
    <mu2>0.9</mu2>
  </gazebo>
  <link name="NAIKI-6DOOR-CLOSET-BODYSET5_link">
    <visual>
      <origin xyz="0.2555 0.438 0.93" rpy="0 -0 0"/>
      <geometry>
        <mesh filename="model://naiki-6door-closet/meshes/NAIKI-6DOOR-CLOSET-BODYSET5_link_mesh.dae" scale="1 1 1" />
      </geometry>
    </visual>
    <collision>
      <origin xyz="0.2555 0.438 0.93" rpy="0 -0 0"/>
      <geometry>
        <mesh filename="model://naiki-6door-closet/meshes/NAIKI-6DOOR-CLOSET-BODYSET5_link_mesh.dae" scale="1 1 1" />
      </geometry>
    </collision>
    <inertial>
      <mass value="0.001" />
      <origin xyz="0 0 0" rpy="0 -0 0"/>
      <inertia ixx="1e-09" ixy="0" ixz="0" iyy="1e-09" iyz="0" izz="1e-09"/>
    </inertial>
  </link>
  <gazebo reference="NAIKI-6DOOR-CLOSET-BODYSET5_link">
    <mu1>0.9</mu1>
    <mu2>0.9</mu2>
  </gazebo>
  <link name="NAIKI-6DOOR-CLOSET-BODYSET4_link">
    <visual>
      <origin xyz="0.2555 -0.148667 0.11" rpy="0 -0 0"/>
      <geometry>
        <mesh filename="model://naiki-6door-closet/meshes/NAIKI-6DOOR-CLOSET-BODYSET4_link_mesh.dae" scale="1 1 1" />
      </geometry>
    </visual>
    <collision>
      <origin xyz="0.2555 -0.148667 0.11" rpy="0 -0 0"/>
      <geometry>
        <mesh filename="model://naiki-6door-closet/meshes/NAIKI-6DOOR-CLOSET-BODYSET4_link_mesh.dae" scale="1 1 1" />
      </geometry>
    </collision>
    <inertial>
      <mass value="0.001" />
      <origin xyz="0 0 0" rpy="0 -0 0"/>
      <inertia ixx="1e-09" ixy="0" ixz="0" iyy="1e-09" iyz="0" izz="1e-09"/>
    </inertial>
  </link>
  <gazebo reference="NAIKI-6DOOR-CLOSET-BODYSET4_link">
    <mu1>0.9</mu1>
    <mu2>0.9</mu2>
  </gazebo>
  <link name="NAIKI-6DOOR-CLOSET-BODYSET3_link">
    <visual>
      <origin xyz="0.2555 0.144667 0.11" rpy="0 -0 0"/>
      <geometry>
        <mesh filename="model://naiki-6door-closet/meshes/NAIKI-6DOOR-CLOSET-BODYSET3_link_mesh.dae" scale="1 1 1" />
      </geometry>
    </visual>
    <collision>
      <origin xyz="0.2555 0.144667 0.11" rpy="0 -0 0"/>
      <geometry>
        <mesh filename="model://naiki-6door-closet/meshes/NAIKI-6DOOR-CLOSET-BODYSET3_link_mesh.dae" scale="1 1 1" />
      </geometry>
    </collision>
    <inertial>
      <mass value="0.001" />
      <origin xyz="0 0 0" rpy="0 -0 0"/>
      <inertia ixx="1e-09" ixy="0" ixz="0" iyy="1e-09" iyz="0" izz="1e-09"/>
    </inertial>
  </link>
  <gazebo reference="NAIKI-6DOOR-CLOSET-BODYSET3_link">
    <mu1>0.9</mu1>
    <mu2>0.9</mu2>
  </gazebo>
  <link name="NAIKI-6DOOR-CLOSET-BODYSET2_link">
    <visual>
      <origin xyz="0.2555 0.438 0.11" rpy="0 -0 0"/>
      <geometry>
        <mesh filename="model://naiki-6door-closet/meshes/NAIKI-6DOOR-CLOSET-BODYSET2_link_mesh.dae" scale="1 1 1" />
      </geometry>
    </visual>
    <collision>
      <origin xyz="0.2555 0.438 0.11" rpy="0 -0 0"/>
      <geometry>
        <mesh filename="model://naiki-6door-closet/meshes/NAIKI-6DOOR-CLOSET-BODYSET2_link_mesh.dae" scale="1 1 1" />
      </geometry>
    </collision>
    <inertial>
      <mass value="0.001" />
      <origin xyz="0 0 0" rpy="0 -0 0"/>
      <inertia ixx="1e-09" ixy="0" ixz="0" iyy="1e-09" iyz="0" izz="1e-09"/>
    </inertial>
  </link>
  <gazebo reference="NAIKI-6DOOR-CLOSET-BODYSET2_link">
    <mu1>0.9</mu1>
    <mu2>0.9</mu2>
  </gazebo>
  <joint name="DOOR0" type="revolute">
    <parent link="ROOT_link"/>
    <child  link="NAIKI-6DOOR-CLOSET-BODYSET7_link"/>
    <origin xyz="0.2555 -0.148667 0.93" rpy="0 -0 0 "/>
    <axis   xyz="0 0 1"/>
    <limit lower="0" upper="1.5708" effort="100" velocity="0.5" />
    <dynamics damping="0.2" friction="0" />
  </joint>
  <transmission type="pr2_mechanism_model/SimpleTransmission" name="DOOR0_trans" >
    <actuator name="DOOR0_motor" />
    <joint name="DOOR0" />
    <mechanicalReduction>1</mechanicalReduction>
  </transmission>
  <gazebo reference="DOOR0">
    <cfmDamping>0.4</cfmDamping>
  </gazebo>
  <joint name="DOOR1" type="revolute">
    <parent link="ROOT_link"/>
    <child  link="NAIKI-6DOOR-CLOSET-BODYSET6_link"/>
    <origin xyz="0.2555 0.144667 0.93" rpy="0 -0 0 "/>
    <axis   xyz="0 0 1"/>
    <limit lower="0" upper="1.5708" effort="100" velocity="0.5" />
    <dynamics damping="0.2" friction="0" />
  </joint>
  <transmission type="pr2_mechanism_model/SimpleTransmission" name="DOOR1_trans" >
    <actuator name="DOOR1_motor" />
    <joint name="DOOR1" />
    <mechanicalReduction>1</mechanicalReduction>
  </transmission>
  <gazebo reference="DOOR1">
    <cfmDamping>0.4</cfmDamping>
  </gazebo>
  <joint name="DOOR2" type="revolute">
    <parent link="ROOT_link"/>
    <child  link="NAIKI-6DOOR-CLOSET-BODYSET5_link"/>
    <origin xyz="0.2555 0.438 0.93" rpy="0 -0 0 "/>
    <axis   xyz="0 0 1"/>
    <limit lower="0" upper="1.5708" effort="100" velocity="0.5" />
    <dynamics damping="0.2" friction="0" />
  </joint>
  <transmission type="pr2_mechanism_model/SimpleTransmission" name="DOOR2_trans" >
    <actuator name="DOOR2_motor" />
    <joint name="DOOR2" />
    <mechanicalReduction>1</mechanicalReduction>
  </transmission>
  <gazebo reference="DOOR2">
    <cfmDamping>0.4</cfmDamping>
  </gazebo>
  <joint name="DOOR3" type="revolute">
    <parent link="ROOT_link"/>
    <child  link="NAIKI-6DOOR-CLOSET-BODYSET4_link"/>
    <origin xyz="0.2555 -0.148667 0.11" rpy="0 -0 0 "/>
    <axis   xyz="0 0 1"/>
    <limit lower="0" upper="1.5708" effort="100" velocity="0.5" />
    <dynamics damping="0.2" friction="0" />
  </joint>
  <transmission type="pr2_mechanism_model/SimpleTransmission" name="DOOR3_trans" >
    <actuator name="DOOR3_motor" />
    <joint name="DOOR3" />
    <mechanicalReduction>1</mechanicalReduction>
  </transmission>
  <gazebo reference="DOOR3">
    <cfmDamping>0.4</cfmDamping>
  </gazebo>
  <joint name="DOOR4" type="revolute">
    <parent link="ROOT_link"/>
    <child  link="NAIKI-6DOOR-CLOSET-BODYSET3_link"/>
    <origin xyz="0.2555 0.144667 0.11" rpy="0 -0 0 "/>
    <axis   xyz="0 0 1"/>
    <limit lower="0" upper="1.5708" effort="100" velocity="0.5" />
    <dynamics damping="0.2" friction="0" />
  </joint>
  <transmission type="pr2_mechanism_model/SimpleTransmission" name="DOOR4_trans" >
    <actuator name="DOOR4_motor" />
    <joint name="DOOR4" />
    <mechanicalReduction>1</mechanicalReduction>
  </transmission>
  <gazebo reference="DOOR4">
    <cfmDamping>0.4</cfmDamping>
  </gazebo>
  <joint name="DOOR5" type="revolute">
    <parent link="ROOT_link"/>
    <child  link="NAIKI-6DOOR-CLOSET-BODYSET2_link"/>
    <origin xyz="0.2555 0.438 0.11" rpy="0 -0 0 "/>
    <axis   xyz="0 0 1"/>
    <limit lower="0" upper="1.5708" effort="100" velocity="0.5" />
    <dynamics damping="0.2" friction="0" />
  </joint>
  <transmission type="pr2_mechanism_model/SimpleTransmission" name="DOOR5_trans" >
    <actuator name="DOOR5_motor" />
    <joint name="DOOR5" />
    <mechanicalReduction>1</mechanicalReduction>
  </transmission>
  <gazebo reference="DOOR5">
    <cfmDamping>0.4</cfmDamping>
  </gazebo>
</robot>
