<?xml version="1.0"?>
<robot name="room73b2-kitchen-shelf"
       xmlns:xi="http://www.w3.org/2001/XInclude"
       xmlns:gazebo="http://playerstage.sourceforge.net/gazebo/xmlschema/#gz"
       xmlns:model="http://playerstage.sourceforge.net/gazebo/xmlschema/#model"
       xmlns:sensor="http://playerstage.sourceforge.net/gazebo/xmlschema/#sensor"
       xmlns:body="http://playerstage.sourceforge.net/gazebo/xmlschema/#body"
       xmlns:geom="http://playerstage.sourceforge.net/gazebo/xmlschema/#geom"
       xmlns:joint="http://playerstage.sourceforge.net/gazebo/xmlschema/#joint"
       xmlns:interface="http://playerstage.sourceforge.net/gazebo/xmlschema/#interface"
       xmlns:rendering="http://playerstage.sourceforge.net/gazebo/xmlschema/#rendering"
       xmlns:renderable="http://playerstage.sourceforge.net/gazebo/xmlschema/#renderable"
       xmlns:controller="http://playerstage.sourceforge.net/gazebo/xmlschema/#controller"
       xmlns:physics="http://playerstage.sourceforge.net/gazebo/xmlschema/#physics">
  <gazebo>
    <static>false</static>
  </gazebo>
  <link name="ROOT_link">
    <visual>
      <origin xyz="0 0 0" rpy="0 -0 0"/>
      <geometry>
        <mesh filename="model://room73b2-kitchen-shelf/meshes/ROOT_link_mesh.dae" scale="1 1 1" />
      </geometry>
    </visual>
    <collision>
      <origin xyz="0 0 0" rpy="0 -0 0"/>
      <geometry>
        <mesh filename="model://room73b2-kitchen-shelf/meshes/ROOT_link_mesh.dae" scale="1 1 1" />
      </geometry>
    </collision>
    <inertial>
      <mass value="0.001" />
      <origin xyz="0 0 0" rpy="0 -0 0"/>
      <inertia ixx="1e-09" ixy="0" ixz="0" iyy="1e-09" iyz="0" izz="1e-09"/>
    </inertial>
  </link>
  <gazebo reference="ROOT_link">
    <mu1>0.9</mu1>
    <mu2>0.9</mu2>
  </gazebo>
  <link name="ROOM73B2-KITCHEN-SHELF-BODYSET7_link">
    <visual>
      <origin xyz="0.18 1.485 0.25" rpy="0 -0 0"/>
      <geometry>
        <mesh filename="model://room73b2-kitchen-shelf/meshes/ROOM73B2-KITCHEN-SHELF-BODYSET7_link_mesh.dae" scale="1 1 1" />
      </geometry>
    </visual>
    <collision>
      <origin xyz="0.18 1.485 0.25" rpy="0 -0 0"/>
      <geometry>
        <mesh filename="model://room73b2-kitchen-shelf/meshes/ROOM73B2-KITCHEN-SHELF-BODYSET7_link_mesh.dae" scale="1 1 1" />
      </geometry>
    </collision>
    <inertial>
      <mass value="0.001" />
      <origin xyz="0 0 0" rpy="0 -0 0"/>
      <inertia ixx="1e-09" ixy="0" ixz="0" iyy="1e-09" iyz="0" izz="1e-09"/>
    </inertial>
  </link>
  <gazebo reference="ROOM73B2-KITCHEN-SHELF-BODYSET7_link">
    <mu1>0.9</mu1>
    <mu2>0.9</mu2>
  </gazebo>
  <link name="ROOM73B2-KITCHEN-SHELF-BODYSET6_link">
    <visual>
      <origin xyz="0.18 0.915 0.25" rpy="0 -0 0"/>
      <geometry>
        <mesh filename="model://room73b2-kitchen-shelf/meshes/ROOM73B2-KITCHEN-SHELF-BODYSET6_link_mesh.dae" scale="1 1 1" />
      </geometry>
    </visual>
    <collision>
      <origin xyz="0.18 0.915 0.25" rpy="0 -0 0"/>
      <geometry>
        <mesh filename="model://room73b2-kitchen-shelf/meshes/ROOM73B2-KITCHEN-SHELF-BODYSET6_link_mesh.dae" scale="1 1 1" />
      </geometry>
    </collision>
    <inertial>
      <mass value="0.001" />
      <origin xyz="0 0 0" rpy="0 -0 0"/>
      <inertia ixx="1e-09" ixy="0" ixz="0" iyy="1e-09" iyz="0" izz="1e-09"/>
    </inertial>
  </link>
  <gazebo reference="ROOM73B2-KITCHEN-SHELF-BODYSET6_link">
    <mu1>0.9</mu1>
    <mu2>0.9</mu2>
  </gazebo>
  <link name="ROOM73B2-KITCHEN-SHELF-BODYSET5_link">
    <visual>
      <origin xyz="0.18 0.885 0.25" rpy="0 -0 0"/>
      <geometry>
        <mesh filename="model://room73b2-kitchen-shelf/meshes/ROOM73B2-KITCHEN-SHELF-BODYSET5_link_mesh.dae" scale="1 1 1" />
      </geometry>
    </visual>
    <collision>
      <origin xyz="0.18 0.885 0.25" rpy="0 -0 0"/>
      <geometry>
        <mesh filename="model://room73b2-kitchen-shelf/meshes/ROOM73B2-KITCHEN-SHELF-BODYSET5_link_mesh.dae" scale="1 1 1" />
      </geometry>
    </collision>
    <inertial>
      <mass value="0.001" />
      <origin xyz="0 0 0" rpy="0 -0 0"/>
      <inertia ixx="1e-09" ixy="0" ixz="0" iyy="1e-09" iyz="0" izz="1e-09"/>
    </inertial>
  </link>
  <gazebo reference="ROOM73B2-KITCHEN-SHELF-BODYSET5_link">
    <mu1>0.9</mu1>
    <mu2>0.9</mu2>
  </gazebo>
  <link name="ROOM73B2-KITCHEN-SHELF-BODYSET4_link">
    <visual>
      <origin xyz="0.18 0.315 0.25" rpy="0 -0 0"/>
      <geometry>
        <mesh filename="model://room73b2-kitchen-shelf/meshes/ROOM73B2-KITCHEN-SHELF-BODYSET4_link_mesh.dae" scale="1 1 1" />
      </geometry>
    </visual>
    <collision>
      <origin xyz="0.18 0.315 0.25" rpy="0 -0 0"/>
      <geometry>
        <mesh filename="model://room73b2-kitchen-shelf/meshes/ROOM73B2-KITCHEN-SHELF-BODYSET4_link_mesh.dae" scale="1 1 1" />
      </geometry>
    </collision>
    <inertial>
      <mass value="0.001" />
      <origin xyz="0 0 0" rpy="0 -0 0"/>
      <inertia ixx="1e-09" ixy="0" ixz="0" iyy="1e-09" iyz="0" izz="1e-09"/>
    </inertial>
  </link>
  <gazebo reference="ROOM73B2-KITCHEN-SHELF-BODYSET4_link">
    <mu1>0.9</mu1>
    <mu2>0.9</mu2>
  </gazebo>
  <link name="ROOM73B2-KITCHEN-SHELF-BODYSET3_link">
    <visual>
      <origin xyz="0.18 0.285 0" rpy="0 -0 0"/>
      <geometry>
        <mesh filename="model://room73b2-kitchen-shelf/meshes/ROOM73B2-KITCHEN-SHELF-BODYSET3_link_mesh.dae" scale="1 1 1" />
      </geometry>
    </visual>
    <collision>
      <origin xyz="0.18 0.285 0" rpy="0 -0 0"/>
      <geometry>
        <mesh filename="model://room73b2-kitchen-shelf/meshes/ROOM73B2-KITCHEN-SHELF-BODYSET3_link_mesh.dae" scale="1 1 1" />
      </geometry>
    </collision>
    <inertial>
      <mass value="0.001" />
      <origin xyz="0 0 0" rpy="0 -0 0"/>
      <inertia ixx="1e-09" ixy="0" ixz="0" iyy="1e-09" iyz="0" izz="1e-09"/>
    </inertial>
  </link>
  <gazebo reference="ROOM73B2-KITCHEN-SHELF-BODYSET3_link">
    <mu1>0.9</mu1>
    <mu2>0.9</mu2>
  </gazebo>
  <link name="ROOM73B2-KITCHEN-SHELF-BODYSET2_link">
    <visual>
      <origin xyz="0.18 -0.285 0" rpy="0 -0 0"/>
      <geometry>
        <mesh filename="model://room73b2-kitchen-shelf/meshes/ROOM73B2-KITCHEN-SHELF-BODYSET2_link_mesh.dae" scale="1 1 1" />
      </geometry>
    </visual>
    <collision>
      <origin xyz="0.18 -0.285 0" rpy="0 -0 0"/>
      <geometry>
        <mesh filename="model://room73b2-kitchen-shelf/meshes/ROOM73B2-KITCHEN-SHELF-BODYSET2_link_mesh.dae" scale="1 1 1" />
      </geometry>
    </collision>
    <inertial>
      <mass value="0.001" />
      <origin xyz="0 0 0" rpy="0 -0 0"/>
      <inertia ixx="1e-09" ixy="0" ixz="0" iyy="1e-09" iyz="0" izz="1e-09"/>
    </inertial>
  </link>
  <gazebo reference="ROOM73B2-KITCHEN-SHELF-BODYSET2_link">
    <mu1>0.9</mu1>
    <mu2>0.9</mu2>
  </gazebo>
  <joint name="DOOR-0" type="revolute">
    <parent link="ROOT_link"/>
    <child  link="ROOM73B2-KITCHEN-SHELF-BODYSET7_link"/>
    <origin xyz="0.18 1.485 0.25" rpy="0 -0 0 "/>
    <axis   xyz="0 0 1"/>
    <limit lower="0" upper="1.5708" effort="100" velocity="0.5" />
    <dynamics damping="0.2" friction="0" />
  </joint>
  <transmission type="pr2_mechanism_model/SimpleTransmission" name="DOOR-0_trans" >
    <actuator name="DOOR-0_motor" />
    <joint name="DOOR-0" />
    <mechanicalReduction>1</mechanicalReduction>
  </transmission>
  <gazebo reference="DOOR-0">
    <cfmDamping>0.4</cfmDamping>
  </gazebo>
  <joint name="DOOR-1" type="revolute">
    <parent link="ROOT_link"/>
    <child  link="ROOM73B2-KITCHEN-SHELF-BODYSET6_link"/>
    <origin xyz="0.18 0.915 0.25" rpy="0 -0 0 "/>
    <axis   xyz="0 0 -1"/>
    <limit lower="0" upper="1.5708" effort="100" velocity="0.5" />
    <dynamics damping="0.2" friction="0" />
  </joint>
  <transmission type="pr2_mechanism_model/SimpleTransmission" name="DOOR-1_trans" >
    <actuator name="DOOR-1_motor" />
    <joint name="DOOR-1" />
    <mechanicalReduction>1</mechanicalReduction>
  </transmission>
  <gazebo reference="DOOR-1">
    <cfmDamping>0.4</cfmDamping>
  </gazebo>
  <joint name="DOOR-2" type="revolute">
    <parent link="ROOT_link"/>
    <child  link="ROOM73B2-KITCHEN-SHELF-BODYSET5_link"/>
    <origin xyz="0.18 0.885 0.25" rpy="0 -0 0 "/>
    <axis   xyz="0 0 1"/>
    <limit lower="0" upper="1.5708" effort="100" velocity="0.5" />
    <dynamics damping="0.2" friction="0" />
  </joint>
  <transmission type="pr2_mechanism_model/SimpleTransmission" name="DOOR-2_trans" >
    <actuator name="DOOR-2_motor" />
    <joint name="DOOR-2" />
    <mechanicalReduction>1</mechanicalReduction>
  </transmission>
  <gazebo reference="DOOR-2">
    <cfmDamping>0.4</cfmDamping>
  </gazebo>
  <joint name="DOOR-3" type="revolute">
    <parent link="ROOT_link"/>
    <child  link="ROOM73B2-KITCHEN-SHELF-BODYSET4_link"/>
    <origin xyz="0.18 0.315 0.25" rpy="0 -0 0 "/>
    <axis   xyz="0 0 -1"/>
    <limit lower="0" upper="1.5708" effort="100" velocity="0.5" />
    <dynamics damping="0.2" friction="0" />
  </joint>
  <transmission type="pr2_mechanism_model/SimpleTransmission" name="DOOR-3_trans" >
    <actuator name="DOOR-3_motor" />
    <joint name="DOOR-3" />
    <mechanicalReduction>1</mechanicalReduction>
  </transmission>
  <gazebo reference="DOOR-3">
    <cfmDamping>0.4</cfmDamping>
  </gazebo>
  <joint name="DOOR-4" type="revolute">
    <parent link="ROOT_link"/>
    <child  link="ROOM73B2-KITCHEN-SHELF-BODYSET3_link"/>
    <origin xyz="0.18 0.285 0" rpy="0 -0 0 "/>
    <axis   xyz="0 0 1"/>
    <limit lower="0" upper="1.5708" effort="100" velocity="0.5" />
    <dynamics damping="0.2" friction="0" />
  </joint>
  <transmission type="pr2_mechanism_model/SimpleTransmission" name="DOOR-4_trans" >
    <actuator name="DOOR-4_motor" />
    <joint name="DOOR-4" />
    <mechanicalReduction>1</mechanicalReduction>
  </transmission>
  <gazebo reference="DOOR-4">
    <cfmDamping>0.4</cfmDamping>
  </gazebo>
  <joint name="DOOR-5" type="revolute">
    <parent link="ROOT_link"/>
    <child  link="ROOM73B2-KITCHEN-SHELF-BODYSET2_link"/>
    <origin xyz="0.18 -0.285 0" rpy="0 -0 0 "/>
    <axis   xyz="0 0 -1"/>
    <limit lower="0" upper="1.5708" effort="100" velocity="0.5" />
    <dynamics damping="0.2" friction="0" />
  </joint>
  <transmission type="pr2_mechanism_model/SimpleTransmission" name="DOOR-5_trans" >
    <actuator name="DOOR-5_motor" />
    <joint name="DOOR-5" />
    <mechanicalReduction>1</mechanicalReduction>
  </transmission>
  <gazebo reference="DOOR-5">
    <cfmDamping>0.4</cfmDamping>
  </gazebo>
</robot>
