<?xml version="1.0"?>
<robot name="room610-laundry-machine"
       xmlns:xi="http://www.w3.org/2001/XInclude"
       xmlns:gazebo="http://playerstage.sourceforge.net/gazebo/xmlschema/#gz"
       xmlns:model="http://playerstage.sourceforge.net/gazebo/xmlschema/#model"
       xmlns:sensor="http://playerstage.sourceforge.net/gazebo/xmlschema/#sensor"
       xmlns:body="http://playerstage.sourceforge.net/gazebo/xmlschema/#body"
       xmlns:geom="http://playerstage.sourceforge.net/gazebo/xmlschema/#geom"
       xmlns:joint="http://playerstage.sourceforge.net/gazebo/xmlschema/#joint"
       xmlns:interface="http://playerstage.sourceforge.net/gazebo/xmlschema/#interface"
       xmlns:rendering="http://playerstage.sourceforge.net/gazebo/xmlschema/#rendering"
       xmlns:renderable="http://playerstage.sourceforge.net/gazebo/xmlschema/#renderable"
       xmlns:controller="http://playerstage.sourceforge.net/gazebo/xmlschema/#controller"
       xmlns:physics="http://playerstage.sourceforge.net/gazebo/xmlschema/#physics">
  <gazebo>
    <static>false</static>
  </gazebo>
  <link name="B0_link">
    <visual>
      <origin xyz="0 0 0" rpy="0 -0 0"/>
      <geometry>
        <mesh filename="model://room610-laundry-machine/meshes/B0_link_mesh.dae" scale="1 1 1" />
      </geometry>
    </visual>
    <collision>
      <origin xyz="0 0 0" rpy="0 -0 0"/>
      <geometry>
        <mesh filename="model://room610-laundry-machine/meshes/B0_link_mesh.dae" scale="1 1 1" />
      </geometry>
    </collision>
    <inertial>
      <mass value="0.001" />
      <origin xyz="0 0 0" rpy="0 -0 0"/>
      <inertia ixx="1e-09" ixy="0" ixz="0" iyy="1e-09" iyz="0" izz="1e-09"/>
    </inertial>
  </link>
  <gazebo reference="B0_link">
    <mu1>0.9</mu1>
    <mu2>0.9</mu2>
  </gazebo>
  <link name="CAP_link">
    <visual>
      <origin xyz="0.64 -0.21 0.77" rpy="1.86187e-16 1.22173 2.65903e-16"/>
      <geometry>
        <mesh filename="model://room610-laundry-machine/meshes/CAP_link_mesh.dae" scale="1 1 1" />
      </geometry>
    </visual>
    <collision>
      <origin xyz="0.64 -0.21 0.77" rpy="1.86187e-16 1.22173 2.65903e-16"/>
      <geometry>
        <mesh filename="model://room610-laundry-machine/meshes/CAP_link_mesh.dae" scale="1 1 1" />
      </geometry>
    </collision>
    <inertial>
      <mass value="0.001" />
      <origin xyz="0 0 0" rpy="0 -0 0"/>
      <inertia ixx="1e-09" ixy="-1.8673e-41" ixz="0" iyy="1e-09" iyz="0" izz="1e-09"/>
    </inertial>
  </link>
  <gazebo reference="CAP_link">
    <mu1>0.9</mu1>
    <mu2>0.9</mu2>
  </gazebo>
  <link name="BUTTON_link">
    <visual>
      <origin xyz="0.6 0.24 0.93" rpy="-9.61482e-17 1.0472 -5.55112e-17"/>
      <geometry>
        <mesh filename="model://room610-laundry-machine/meshes/BUTTON_link_mesh.dae" scale="1 1 1" />
      </geometry>
    </visual>
    <collision>
      <origin xyz="0.6 0.24 0.93" rpy="-9.61482e-17 1.0472 -5.55112e-17"/>
      <geometry>
        <mesh filename="model://room610-laundry-machine/meshes/BUTTON_link_mesh.dae" scale="1 1 1" />
      </geometry>
    </collision>
    <inertial>
      <mass value="0.001" />
      <origin xyz="0 0 0" rpy="0 -0 0"/>
      <inertia ixx="1e-09" ixy="8.88656e-42" ixz="-9.86076e-32" iyy="1e-09" iyz="0" izz="1e-09"/>
    </inertial>
  </link>
  <gazebo reference="BUTTON_link">
    <mu1>0.9</mu1>
    <mu2>0.9</mu2>
  </gazebo>
  <joint name="JOINT0" type="revolute">
    <parent link="B0_link"/>
    <child  link="CAP_link"/>
    <origin xyz="0.64 -0.21 0.77" rpy="1.86187e-16 1.22173 2.65903e-16 "/>
    <axis   xyz="0.34202 9.09441e-17 -0.939693"/>
    <limit lower="0" upper="3.14159" effort="100" velocity="0.5" />
    <dynamics damping="0.2" friction="0" />
  </joint>
  <transmission type="pr2_mechanism_model/SimpleTransmission" name="JOINT0_trans" >
    <actuator name="JOINT0_motor" />
    <joint name="JOINT0" />
    <mechanicalReduction>1</mechanicalReduction>
  </transmission>
  <gazebo reference="JOINT0">
    <cfmDamping>0.4</cfmDamping>
  </gazebo>
  <joint name="JOINT1" type="prismatic">
    <parent link="B0_link"/>
    <child  link="BUTTON_link"/>
    <origin xyz="0.6 0.24 0.93" rpy="-9.61482e-17 1.0472 -5.55112e-17 "/>
    <axis   xyz="0.866025 4.80741e-17 0.5"/>
    <limit lower="-0.09" upper="0.09" effort="100" velocity="0.01" />
    <dynamics damping="0.2" friction="0" />
  </joint>
  <transmission type="pr2_mechanism_model/SimpleTransmission" name="JOINT1_trans" >
    <actuator name="JOINT1_motor" />
    <joint name="JOINT1" />
    <mechanicalReduction>1</mechanicalReduction>
  </transmission>
  <gazebo reference="JOINT1">
    <cfmDamping>0.4</cfmDamping>
  </gazebo>
</robot>
