<?xml version="1.0"?>
<robot name="room73a3-officeprinter"
       xmlns:xi="http://www.w3.org/2001/XInclude"
       xmlns:gazebo="http://playerstage.sourceforge.net/gazebo/xmlschema/#gz"
       xmlns:model="http://playerstage.sourceforge.net/gazebo/xmlschema/#model"
       xmlns:sensor="http://playerstage.sourceforge.net/gazebo/xmlschema/#sensor"
       xmlns:body="http://playerstage.sourceforge.net/gazebo/xmlschema/#body"
       xmlns:geom="http://playerstage.sourceforge.net/gazebo/xmlschema/#geom"
       xmlns:joint="http://playerstage.sourceforge.net/gazebo/xmlschema/#joint"
       xmlns:interface="http://playerstage.sourceforge.net/gazebo/xmlschema/#interface"
       xmlns:rendering="http://playerstage.sourceforge.net/gazebo/xmlschema/#rendering"
       xmlns:renderable="http://playerstage.sourceforge.net/gazebo/xmlschema/#renderable"
       xmlns:controller="http://playerstage.sourceforge.net/gazebo/xmlschema/#controller"
       xmlns:physics="http://playerstage.sourceforge.net/gazebo/xmlschema/#physics">
  <gazebo>
    <static>false</static>
  </gazebo>
  <link name="PRINTER_link">
    <visual>
      <origin xyz="0 0 0" rpy="0 -0 0"/>
      <geometry>
        <mesh filename="model://room73a3-officeprinter/meshes/PRINTER_link_mesh.dae" scale="1 1 1" />
      </geometry>
    </visual>
    <collision>
      <origin xyz="0 0 0" rpy="0 -0 0"/>
      <geometry>
        <mesh filename="model://room73a3-officeprinter/meshes/PRINTER_link_mesh.dae" scale="1 1 1" />
      </geometry>
    </collision>
    <inertial>
      <mass value="0.001" />
      <origin xyz="0 0 0" rpy="0 -0 0"/>
      <inertia ixx="1e-09" ixy="0" ixz="0" iyy="1e-09" iyz="0" izz="1e-09"/>
    </inertial>
  </link>
  <gazebo reference="PRINTER_link">
    <mu1>0.9</mu1>
    <mu2>0.9</mu2>
  </gazebo>
  <link name="SCANNER_link">
    <visual>
      <origin xyz="0 0 0.984" rpy="0 -0 0"/>
      <geometry>
        <mesh filename="model://room73a3-officeprinter/meshes/SCANNER_link_mesh.dae" scale="1 1 1" />
      </geometry>
    </visual>
    <collision>
      <origin xyz="0 0 0.984" rpy="0 -0 0"/>
      <geometry>
        <mesh filename="model://room73a3-officeprinter/meshes/SCANNER_link_mesh.dae" scale="1 1 1" />
      </geometry>
    </collision>
    <inertial>
      <mass value="0.001" />
      <origin xyz="0 0 0" rpy="0 -0 0"/>
      <inertia ixx="1e-09" ixy="0" ixz="0" iyy="1e-09" iyz="0" izz="1e-09"/>
    </inertial>
  </link>
  <gazebo reference="SCANNER_link">
    <mu1>0.9</mu1>
    <mu2>0.9</mu2>
  </gazebo>
  <joint name="JOINT0" type="revolute">
    <parent link="PRINTER_link"/>
    <child  link="SCANNER_link"/>
    <origin xyz="0 0 0.984" rpy="0 -0 0 "/>
    <axis   xyz="0 -1 0"/>
    <limit lower="0" upper="3.14159" effort="100" velocity="0.5" />
    <dynamics damping="0.2" friction="0" />
  </joint>
  <transmission type="pr2_mechanism_model/SimpleTransmission" name="JOINT0_trans" >
    <actuator name="JOINT0_motor" />
    <joint name="JOINT0" />
    <mechanicalReduction>1</mechanicalReduction>
  </transmission>
  <gazebo reference="JOINT0">
    <cfmDamping>0.4</cfmDamping>
  </gazebo>
</robot>
