<?xml version="1.0"?>
<robot name="toshiba-microwave-oven"
       xmlns:xi="http://www.w3.org/2001/XInclude"
       xmlns:gazebo="http://playerstage.sourceforge.net/gazebo/xmlschema/#gz"
       xmlns:model="http://playerstage.sourceforge.net/gazebo/xmlschema/#model"
       xmlns:sensor="http://playerstage.sourceforge.net/gazebo/xmlschema/#sensor"
       xmlns:body="http://playerstage.sourceforge.net/gazebo/xmlschema/#body"
       xmlns:geom="http://playerstage.sourceforge.net/gazebo/xmlschema/#geom"
       xmlns:joint="http://playerstage.sourceforge.net/gazebo/xmlschema/#joint"
       xmlns:interface="http://playerstage.sourceforge.net/gazebo/xmlschema/#interface"
       xmlns:rendering="http://playerstage.sourceforge.net/gazebo/xmlschema/#rendering"
       xmlns:renderable="http://playerstage.sourceforge.net/gazebo/xmlschema/#renderable"
       xmlns:controller="http://playerstage.sourceforge.net/gazebo/xmlschema/#controller"
       xmlns:physics="http://playerstage.sourceforge.net/gazebo/xmlschema/#physics">
  <gazebo>
    <static>false</static>
  </gazebo>
  <link name="ROOT_link">
    <visual>
      <origin xyz="0 0 0" rpy="0 -0 0"/>
      <geometry>
        <mesh filename="model://toshiba-microwave-oven/meshes/ROOT_link_mesh.dae" scale="1 1 1" />
      </geometry>
    </visual>
    <collision>
      <origin xyz="0 0 0" rpy="0 -0 0"/>
      <geometry>
        <mesh filename="model://toshiba-microwave-oven/meshes/ROOT_link_mesh.dae" scale="1 1 1" />
      </geometry>
    </collision>
    <inertial>
      <mass value="0.001" />
      <origin xyz="0 0 0" rpy="0 -0 0"/>
      <inertia ixx="1e-09" ixy="0" ixz="0" iyy="1e-09" iyz="0" izz="1e-09"/>
    </inertial>
  </link>
  <gazebo reference="ROOT_link">
    <mu1>0.9</mu1>
    <mu2>0.9</mu2>
  </gazebo>
  <link name="TOSHIBA-MICROWAVE-OVEN-BODYSET2_link">
    <visual>
      <origin xyz="0.175 -0.225 0.05" rpy="0 -0 0"/>
      <geometry>
        <mesh filename="model://toshiba-microwave-oven/meshes/TOSHIBA-MICROWAVE-OVEN-BODYSET2_link_mesh.dae" scale="1 1 1" />
      </geometry>
    </visual>
    <collision>
      <origin xyz="0.175 -0.225 0.05" rpy="0 -0 0"/>
      <geometry>
        <mesh filename="model://toshiba-microwave-oven/meshes/TOSHIBA-MICROWAVE-OVEN-BODYSET2_link_mesh.dae" scale="1 1 1" />
      </geometry>
    </collision>
    <inertial>
      <mass value="0.001" />
      <origin xyz="0 0 0" rpy="0 -0 0"/>
      <inertia ixx="1e-09" ixy="0" ixz="0" iyy="1e-09" iyz="0" izz="1e-09"/>
    </inertial>
  </link>
  <gazebo reference="TOSHIBA-MICROWAVE-OVEN-BODYSET2_link">
    <mu1>0.9</mu1>
    <mu2>0.9</mu2>
  </gazebo>
  <link name="TOSHIBA-MICROWAVE-OVEN-BODYSET3_link">
    <visual>
      <origin xyz="0.21 0.21 0.085" rpy="0 -1.5708 0"/>
      <geometry>
        <mesh filename="model://toshiba-microwave-oven/meshes/TOSHIBA-MICROWAVE-OVEN-BODYSET3_link_mesh.dae" scale="1 1 1" />
      </geometry>
    </visual>
    <collision>
      <origin xyz="0.21 0.21 0.085" rpy="0 -1.5708 0"/>
      <geometry>
        <mesh filename="model://toshiba-microwave-oven/meshes/TOSHIBA-MICROWAVE-OVEN-BODYSET3_link_mesh.dae" scale="1 1 1" />
      </geometry>
    </collision>
    <inertial>
      <mass value="0.001" />
      <origin xyz="0 0 0" rpy="0 -0 0"/>
      <inertia ixx="1e-09" ixy="3.73079e-42" ixz="0" iyy="1e-09" iyz="0" izz="1e-09"/>
    </inertial>
  </link>
  <gazebo reference="TOSHIBA-MICROWAVE-OVEN-BODYSET3_link">
    <mu1>0.9</mu1>
    <mu2>0.9</mu2>
  </gazebo>
  <joint name="DOOR" type="revolute">
    <parent link="ROOT_link"/>
    <child  link="TOSHIBA-MICROWAVE-OVEN-BODYSET2_link"/>
    <origin xyz="0.175 -0.225 0.05" rpy="0 -0 0 "/>
    <axis   xyz="0 1 0"/>
    <limit lower="0" upper="1.5708" effort="100" velocity="0.5" />
    <dynamics damping="0.2" friction="0" />
  </joint>
  <transmission type="pr2_mechanism_model/SimpleTransmission" name="DOOR_trans" >
    <actuator name="DOOR_motor" />
    <joint name="DOOR" />
    <mechanicalReduction>1</mechanicalReduction>
  </transmission>
  <gazebo reference="DOOR">
    <cfmDamping>0.4</cfmDamping>
  </gazebo>
  <joint name="KNOB" type="revolute">
    <parent link="ROOT_link"/>
    <child  link="TOSHIBA-MICROWAVE-OVEN-BODYSET3_link"/>
    <origin xyz="0.21 0.21 0.085" rpy="0 -1.5708 0 "/>
    <axis   xyz="1 0 -3.33067e-16"/>
    <limit lower="0" upper="6.28319" effort="100" velocity="0.5" />
    <dynamics damping="0.2" friction="0" />
  </joint>
  <transmission type="pr2_mechanism_model/SimpleTransmission" name="KNOB_trans" >
    <actuator name="KNOB_motor" />
    <joint name="KNOB" />
    <mechanicalReduction>1</mechanicalReduction>
  </transmission>
  <gazebo reference="KNOB">
    <cfmDamping>0.4</cfmDamping>
  </gazebo>
</robot>
