<?xml version="1.0"?>
<robot name="akiba-door-window"
       xmlns:xi="http://www.w3.org/2001/XInclude"
       xmlns:gazebo="http://playerstage.sourceforge.net/gazebo/xmlschema/#gz"
       xmlns:model="http://playerstage.sourceforge.net/gazebo/xmlschema/#model"
       xmlns:sensor="http://playerstage.sourceforge.net/gazebo/xmlschema/#sensor"
       xmlns:body="http://playerstage.sourceforge.net/gazebo/xmlschema/#body"
       xmlns:geom="http://playerstage.sourceforge.net/gazebo/xmlschema/#geom"
       xmlns:joint="http://playerstage.sourceforge.net/gazebo/xmlschema/#joint"
       xmlns:interface="http://playerstage.sourceforge.net/gazebo/xmlschema/#interface"
       xmlns:rendering="http://playerstage.sourceforge.net/gazebo/xmlschema/#rendering"
       xmlns:renderable="http://playerstage.sourceforge.net/gazebo/xmlschema/#renderable"
       xmlns:controller="http://playerstage.sourceforge.net/gazebo/xmlschema/#controller"
       xmlns:physics="http://playerstage.sourceforge.net/gazebo/xmlschema/#physics">
  <gazebo>
    <static>false</static>
  </gazebo>
  <link name="AKIBA-DOOR-WINDOW-BODYSET2_link">
    <visual>
      <origin xyz="0 0 0" rpy="0 -0 0"/>
      <geometry>
        <mesh filename="model://akiba-door-window/meshes/AKIBA-DOOR-WINDOW-BODYSET2_link_mesh.dae" scale="1 1 1" />
      </geometry>
    </visual>
    <collision>
      <origin xyz="0 0 0" rpy="0 -0 0"/>
      <geometry>
        <mesh filename="model://akiba-door-window/meshes/AKIBA-DOOR-WINDOW-BODYSET2_link_mesh.dae" scale="1 1 1" />
      </geometry>
    </collision>
    <inertial>
      <mass value="0.001" />
      <origin xyz="0 0 0" rpy="0 -0 0"/>
      <inertia ixx="1e-09" ixy="0" ixz="0" iyy="1e-09" iyz="0" izz="1e-09"/>
    </inertial>
  </link>
  <gazebo reference="AKIBA-DOOR-WINDOW-BODYSET2_link">
    <mu1>0.9</mu1>
    <mu2>0.9</mu2>
  </gazebo>
  <link name="AKIBA-DOOR-WINDOW-BODYSET3_link">
    <visual>
      <origin xyz="-0.015 -0.295 0" rpy="0 -0 0"/>
      <geometry>
        <mesh filename="model://akiba-door-window/meshes/AKIBA-DOOR-WINDOW-BODYSET3_link_mesh.dae" scale="1 1 1" />
      </geometry>
    </visual>
    <collision>
      <origin xyz="-0.015 -0.295 0" rpy="0 -0 0"/>
      <geometry>
        <mesh filename="model://akiba-door-window/meshes/AKIBA-DOOR-WINDOW-BODYSET3_link_mesh.dae" scale="1 1 1" />
      </geometry>
    </collision>
    <inertial>
      <mass value="0.001" />
      <origin xyz="0 0 0" rpy="0 -0 0"/>
      <inertia ixx="1e-09" ixy="0" ixz="0" iyy="1e-09" iyz="0" izz="1e-09"/>
    </inertial>
  </link>
  <gazebo reference="AKIBA-DOOR-WINDOW-BODYSET3_link">
    <mu1>0.9</mu1>
    <mu2>0.9</mu2>
  </gazebo>
  <joint name="DOOR" type="revolute">
    <parent link="AKIBA-DOOR-WINDOW-BODYSET2_link"/>
    <child  link="AKIBA-DOOR-WINDOW-BODYSET3_link"/>
    <origin xyz="-0.015 -0.295 0" rpy="0 -0 0 "/>
    <axis   xyz="0 0 -1"/>
    <limit lower="0" upper="1.5708" effort="100" velocity="0.5" />
    <dynamics damping="0.2" friction="0" />
  </joint>
  <transmission type="pr2_mechanism_model/SimpleTransmission" name="DOOR_trans" >
    <actuator name="DOOR_motor" />
    <joint name="DOOR" />
    <mechanicalReduction>1</mechanicalReduction>
  </transmission>
  <gazebo reference="DOOR">
    <cfmDamping>0.4</cfmDamping>
  </gazebo>
</robot>
