<?xml version="1.0"?>
<robot name="room602-door-right"
       xmlns:xi="http://www.w3.org/2001/XInclude"
       xmlns:gazebo="http://playerstage.sourceforge.net/gazebo/xmlschema/#gz"
       xmlns:model="http://playerstage.sourceforge.net/gazebo/xmlschema/#model"
       xmlns:sensor="http://playerstage.sourceforge.net/gazebo/xmlschema/#sensor"
       xmlns:body="http://playerstage.sourceforge.net/gazebo/xmlschema/#body"
       xmlns:geom="http://playerstage.sourceforge.net/gazebo/xmlschema/#geom"
       xmlns:joint="http://playerstage.sourceforge.net/gazebo/xmlschema/#joint"
       xmlns:interface="http://playerstage.sourceforge.net/gazebo/xmlschema/#interface"
       xmlns:rendering="http://playerstage.sourceforge.net/gazebo/xmlschema/#rendering"
       xmlns:renderable="http://playerstage.sourceforge.net/gazebo/xmlschema/#renderable"
       xmlns:controller="http://playerstage.sourceforge.net/gazebo/xmlschema/#controller"
       xmlns:physics="http://playerstage.sourceforge.net/gazebo/xmlschema/#physics">
  <gazebo>
    <static>false</static>
  </gazebo>
  <link name="ROOM602-DOOR-RIGHT-BODYSET2_link">
    <visual>
      <origin xyz="0 0 0" rpy="0 -0 0"/>
      <geometry>
        <mesh filename="model://room602-door-right/meshes/ROOM602-DOOR-RIGHT-BODYSET2_link_mesh.dae" scale="1 1 1" />
      </geometry>
    </visual>
    <collision>
      <origin xyz="0 0 0" rpy="0 -0 0"/>
      <geometry>
        <mesh filename="model://room602-door-right/meshes/ROOM602-DOOR-RIGHT-BODYSET2_link_mesh.dae" scale="1 1 1" />
      </geometry>
    </collision>
    <inertial>
      <mass value="0.001" />
      <origin xyz="0 0 0" rpy="0 -0 0"/>
      <inertia ixx="1e-09" ixy="0" ixz="0" iyy="1e-09" iyz="0" izz="1e-09"/>
    </inertial>
  </link>
  <gazebo reference="ROOM602-DOOR-RIGHT-BODYSET2_link">
    <mu1>0.9</mu1>
    <mu2>0.9</mu2>
  </gazebo>
  <link name="ROOM602-DOOR-RIGHT-BODYSET3_link">
    <visual>
      <origin xyz="-0.017 0.017 0" rpy="0 -0 0"/>
      <geometry>
        <mesh filename="model://room602-door-right/meshes/ROOM602-DOOR-RIGHT-BODYSET3_link_mesh.dae" scale="1 1 1" />
      </geometry>
    </visual>
    <collision>
      <origin xyz="-0.017 0.017 0" rpy="0 -0 0"/>
      <geometry>
        <mesh filename="model://room602-door-right/meshes/ROOM602-DOOR-RIGHT-BODYSET3_link_mesh.dae" scale="1 1 1" />
      </geometry>
    </collision>
    <inertial>
      <mass value="0.001" />
      <origin xyz="0 0 0" rpy="0 -0 0"/>
      <inertia ixx="1e-09" ixy="0" ixz="0" iyy="1e-09" iyz="0" izz="1e-09"/>
    </inertial>
  </link>
  <gazebo reference="ROOM602-DOOR-RIGHT-BODYSET3_link">
    <mu1>0.9</mu1>
    <mu2>0.9</mu2>
  </gazebo>
  <link name="ROOM602-DOOR-RIGHT-BODYSET5_link">
    <visual>
      <origin xyz="-0.088 0.713 0.91" rpy="0 -0 0"/>
      <geometry>
        <mesh filename="model://room602-door-right/meshes/ROOM602-DOOR-RIGHT-BODYSET5_link_mesh.dae" scale="1 1 1" />
      </geometry>
    </visual>
    <collision>
      <origin xyz="-0.088 0.713 0.91" rpy="0 -0 0"/>
      <geometry>
        <mesh filename="model://room602-door-right/meshes/ROOM602-DOOR-RIGHT-BODYSET5_link_mesh.dae" scale="1 1 1" />
      </geometry>
    </collision>
    <inertial>
      <mass value="0.001" />
      <origin xyz="0 0 0" rpy="0 -0 0"/>
      <inertia ixx="1e-09" ixy="0" ixz="0" iyy="1e-09" iyz="0" izz="1e-09"/>
    </inertial>
  </link>
  <gazebo reference="ROOM602-DOOR-RIGHT-BODYSET5_link">
    <mu1>0.9</mu1>
    <mu2>0.9</mu2>
  </gazebo>
  <link name="ROOM602-DOOR-RIGHT-BODYSET4_link">
    <visual>
      <origin xyz="0.0345 0.713 1.01" rpy="0 -0 0"/>
      <geometry>
        <mesh filename="model://room602-door-right/meshes/ROOM602-DOOR-RIGHT-BODYSET4_link_mesh.dae" scale="1 1 1" />
      </geometry>
    </visual>
    <collision>
      <origin xyz="0.0345 0.713 1.01" rpy="0 -0 0"/>
      <geometry>
        <mesh filename="model://room602-door-right/meshes/ROOM602-DOOR-RIGHT-BODYSET4_link_mesh.dae" scale="1 1 1" />
      </geometry>
    </collision>
    <inertial>
      <mass value="0.001" />
      <origin xyz="0.088 -0.713 -0.91" rpy="0 -0 0"/>
      <inertia ixx="1e-09" ixy="0" ixz="0" iyy="1e-09" iyz="0" izz="1e-09"/>
    </inertial>
  </link>
  <gazebo reference="ROOM602-DOOR-RIGHT-BODYSET4_link">
    <mu1>0.9</mu1>
    <mu2>0.9</mu2>
  </gazebo>
  <joint name="DOOR" type="revolute">
    <parent link="ROOM602-DOOR-RIGHT-BODYSET2_link"/>
    <child  link="ROOM602-DOOR-RIGHT-BODYSET3_link"/>
    <origin xyz="-0.017 0.017 0" rpy="0 -0 0 "/>
    <axis   xyz="0 0 -1"/>
    <limit lower="0" upper="1.5708" effort="100" velocity="0.5" />
    <dynamics damping="0.2" friction="0" />
  </joint>
  <transmission type="pr2_mechanism_model/SimpleTransmission" name="DOOR_trans" >
    <actuator name="DOOR_motor" />
    <joint name="DOOR" />
    <mechanicalReduction>1</mechanicalReduction>
  </transmission>
  <gazebo reference="DOOR">
    <cfmDamping>0.4</cfmDamping>
  </gazebo>
  <joint name="KNOB" type="revolute">
    <parent link="ROOM602-DOOR-RIGHT-BODYSET3_link"/>
    <child  link="ROOM602-DOOR-RIGHT-BODYSET5_link"/>
    <origin xyz="-0.088 0.713 0.91" rpy="0 -0 0 "/>
    <axis   xyz="1 0 0"/>
    <limit lower="0" upper="1.5708" effort="100" velocity="0.5" />
    <dynamics damping="0.2" friction="0" />
  </joint>
  <transmission type="pr2_mechanism_model/SimpleTransmission" name="KNOB_trans" >
    <actuator name="KNOB_motor" />
    <joint name="KNOB" />
    <mechanicalReduction>1</mechanicalReduction>
  </transmission>
  <gazebo reference="KNOB">
    <cfmDamping>0.4</cfmDamping>
  </gazebo>
  <joint name="LOCK" type="revolute">
    <parent link="ROOM602-DOOR-RIGHT-BODYSET5_link"/>
    <child  link="ROOM602-DOOR-RIGHT-BODYSET4_link"/>
    <origin xyz="0.0345 0.713 1.01" rpy="0 -0 0 "/>
    <axis   xyz="1 0 0"/>
    <limit lower="-1.5708" upper="0" effort="100" velocity="0.5" />
    <dynamics damping="0.2" friction="0" />
  </joint>
  <transmission type="pr2_mechanism_model/SimpleTransmission" name="LOCK_trans" >
    <actuator name="LOCK_motor" />
    <joint name="LOCK" />
    <mechanicalReduction>1</mechanicalReduction>
  </transmission>
  <gazebo reference="LOCK">
    <cfmDamping>0.4</cfmDamping>
  </gazebo>
</robot>
