<?xml version="1.0"?>
<robot name="room602-wheelchair"
       xmlns:xi="http://www.w3.org/2001/XInclude"
       xmlns:gazebo="http://playerstage.sourceforge.net/gazebo/xmlschema/#gz"
       xmlns:model="http://playerstage.sourceforge.net/gazebo/xmlschema/#model"
       xmlns:sensor="http://playerstage.sourceforge.net/gazebo/xmlschema/#sensor"
       xmlns:body="http://playerstage.sourceforge.net/gazebo/xmlschema/#body"
       xmlns:geom="http://playerstage.sourceforge.net/gazebo/xmlschema/#geom"
       xmlns:joint="http://playerstage.sourceforge.net/gazebo/xmlschema/#joint"
       xmlns:interface="http://playerstage.sourceforge.net/gazebo/xmlschema/#interface"
       xmlns:rendering="http://playerstage.sourceforge.net/gazebo/xmlschema/#rendering"
       xmlns:renderable="http://playerstage.sourceforge.net/gazebo/xmlschema/#renderable"
       xmlns:controller="http://playerstage.sourceforge.net/gazebo/xmlschema/#controller"
       xmlns:physics="http://playerstage.sourceforge.net/gazebo/xmlschema/#physics">
  <gazebo>
    <static>false</static>
  </gazebo>
  <link name="ROOM602-WHEELCHAIR-BODYSET2_link">
    <visual>
      <origin xyz="0 0 0" rpy="0 -0 0"/>
      <geometry>
        <mesh filename="model://room602-wheelchair/meshes/ROOM602-WHEELCHAIR-BODYSET2_link_mesh.dae" scale="1 1 1" />
      </geometry>
    </visual>
    <collision>
      <origin xyz="0 0 0" rpy="0 -0 0"/>
      <geometry>
        <mesh filename="model://room602-wheelchair/meshes/ROOM602-WHEELCHAIR-BODYSET2_link_mesh.dae" scale="1 1 1" />
      </geometry>
    </collision>
    <inertial>
      <mass value="0.001" />
      <origin xyz="0 0 0" rpy="0 -0 0"/>
      <inertia ixx="1e-09" ixy="0" ixz="0" iyy="1e-09" iyz="0" izz="1e-09"/>
    </inertial>
  </link>
  <gazebo reference="ROOM602-WHEELCHAIR-BODYSET2_link">
    <mu1>0.9</mu1>
    <mu2>0.9</mu2>
  </gazebo>
  <link name="LEFT-LARGE_link">
    <visual>
      <origin xyz="0 0.23 0" rpy="0 -0 0"/>
      <geometry>
        <mesh filename="model://room602-wheelchair/meshes/LEFT-LARGE_link_mesh.dae" scale="1 1 1" />
      </geometry>
    </visual>
    <collision>
      <origin xyz="0 0.23 0" rpy="0 -0 0"/>
      <geometry>
        <mesh filename="model://room602-wheelchair/meshes/LEFT-LARGE_link_mesh.dae" scale="1 1 1" />
      </geometry>
    </collision>
    <inertial>
      <mass value="0.001" />
      <origin xyz="0 0 0" rpy="0 -0 0"/>
      <inertia ixx="1e-09" ixy="0" ixz="0" iyy="1e-09" iyz="0" izz="1e-09"/>
    </inertial>
  </link>
  <gazebo reference="LEFT-LARGE_link">
    <mu1>0.9</mu1>
    <mu2>0.9</mu2>
  </gazebo>
  <link name="LEFT-SMALL_link">
    <visual>
      <origin xyz="0.21 0.23 0.075" rpy="0 -0 0"/>
      <geometry>
        <mesh filename="model://room602-wheelchair/meshes/LEFT-SMALL_link_mesh.dae" scale="1 1 1" />
      </geometry>
    </visual>
    <collision>
      <origin xyz="0.21 0.23 0.075" rpy="0 -0 0"/>
      <geometry>
        <mesh filename="model://room602-wheelchair/meshes/LEFT-SMALL_link_mesh.dae" scale="1 1 1" />
      </geometry>
    </collision>
    <inertial>
      <mass value="0.001" />
      <origin xyz="0 0 0" rpy="0 -0 0"/>
      <inertia ixx="1e-09" ixy="0" ixz="0" iyy="1e-09" iyz="0" izz="1e-09"/>
    </inertial>
  </link>
  <gazebo reference="LEFT-SMALL_link">
    <mu1>0.9</mu1>
    <mu2>0.9</mu2>
  </gazebo>
  <link name="RIGHT-LARGE_link">
    <visual>
      <origin xyz="0 -0.23 0" rpy="0 -0 0"/>
      <geometry>
        <mesh filename="model://room602-wheelchair/meshes/RIGHT-LARGE_link_mesh.dae" scale="1 1 1" />
      </geometry>
    </visual>
    <collision>
      <origin xyz="0 -0.23 0" rpy="0 -0 0"/>
      <geometry>
        <mesh filename="model://room602-wheelchair/meshes/RIGHT-LARGE_link_mesh.dae" scale="1 1 1" />
      </geometry>
    </collision>
    <inertial>
      <mass value="0.001" />
      <origin xyz="0 0 0" rpy="0 -0 0"/>
      <inertia ixx="1e-09" ixy="0" ixz="0" iyy="1e-09" iyz="0" izz="1e-09"/>
    </inertial>
  </link>
  <gazebo reference="RIGHT-LARGE_link">
    <mu1>0.9</mu1>
    <mu2>0.9</mu2>
  </gazebo>
  <link name="RIGHT-SMALL_link">
    <visual>
      <origin xyz="0.21 -0.23 0.075" rpy="0 -0 0"/>
      <geometry>
        <mesh filename="model://room602-wheelchair/meshes/RIGHT-SMALL_link_mesh.dae" scale="1 1 1" />
      </geometry>
    </visual>
    <collision>
      <origin xyz="0.21 -0.23 0.075" rpy="0 -0 0"/>
      <geometry>
        <mesh filename="model://room602-wheelchair/meshes/RIGHT-SMALL_link_mesh.dae" scale="1 1 1" />
      </geometry>
    </collision>
    <inertial>
      <mass value="0.001" />
      <origin xyz="0 0 0" rpy="0 -0 0"/>
      <inertia ixx="1e-09" ixy="0" ixz="0" iyy="1e-09" iyz="0" izz="1e-09"/>
    </inertial>
  </link>
  <gazebo reference="RIGHT-SMALL_link">
    <mu1>0.9</mu1>
    <mu2>0.9</mu2>
  </gazebo>
  <joint name="LEFT-LARGE" type="revolute">
    <parent link="ROOM602-WHEELCHAIR-BODYSET2_link"/>
    <child  link="LEFT-LARGE_link"/>
    <origin xyz="0 0.23 0" rpy="0 -0 0 "/>
    <axis   xyz="0 0 -1"/>
    <limit lower="-1.5708" upper="1.5708" effort="100" velocity="0.5" />
    <dynamics damping="0.2" friction="0" />
  </joint>
  <transmission type="pr2_mechanism_model/SimpleTransmission" name="LEFT-LARGE_trans" >
    <actuator name="LEFT-LARGE_motor" />
    <joint name="LEFT-LARGE" />
    <mechanicalReduction>1</mechanicalReduction>
  </transmission>
  <gazebo reference="LEFT-LARGE">
    <cfmDamping>0.4</cfmDamping>
  </gazebo>
  <joint name="LEFT-SMALL" type="revolute">
    <parent link="ROOM602-WHEELCHAIR-BODYSET2_link"/>
    <child  link="LEFT-SMALL_link"/>
    <origin xyz="0.21 0.23 0.075" rpy="0 -0 0 "/>
    <axis   xyz="0 0 -1"/>
    <limit lower="-1.5708" upper="1.5708" effort="100" velocity="0.5" />
    <dynamics damping="0.2" friction="0" />
  </joint>
  <transmission type="pr2_mechanism_model/SimpleTransmission" name="LEFT-SMALL_trans" >
    <actuator name="LEFT-SMALL_motor" />
    <joint name="LEFT-SMALL" />
    <mechanicalReduction>1</mechanicalReduction>
  </transmission>
  <gazebo reference="LEFT-SMALL">
    <cfmDamping>0.4</cfmDamping>
  </gazebo>
  <joint name="RIGHT-LARGE" type="revolute">
    <parent link="ROOM602-WHEELCHAIR-BODYSET2_link"/>
    <child  link="RIGHT-LARGE_link"/>
    <origin xyz="0 -0.23 0" rpy="0 -0 0 "/>
    <axis   xyz="0 0 -1"/>
    <limit lower="-1.5708" upper="1.5708" effort="100" velocity="0.5" />
    <dynamics damping="0.2" friction="0" />
  </joint>
  <transmission type="pr2_mechanism_model/SimpleTransmission" name="RIGHT-LARGE_trans" >
    <actuator name="RIGHT-LARGE_motor" />
    <joint name="RIGHT-LARGE" />
    <mechanicalReduction>1</mechanicalReduction>
  </transmission>
  <gazebo reference="RIGHT-LARGE">
    <cfmDamping>0.4</cfmDamping>
  </gazebo>
  <joint name="RIGHT-SMALL" type="revolute">
    <parent link="ROOM602-WHEELCHAIR-BODYSET2_link"/>
    <child  link="RIGHT-SMALL_link"/>
    <origin xyz="0.21 -0.23 0.075" rpy="0 -0 0 "/>
    <axis   xyz="0 0 -1"/>
    <limit lower="-1.5708" upper="1.5708" effort="100" velocity="0.5" />
    <dynamics damping="0.2" friction="0" />
  </joint>
  <transmission type="pr2_mechanism_model/SimpleTransmission" name="RIGHT-SMALL_trans" >
    <actuator name="RIGHT-SMALL_motor" />
    <joint name="RIGHT-SMALL" />
    <mechanicalReduction>1</mechanicalReduction>
  </transmission>
  <gazebo reference="RIGHT-SMALL">
    <cfmDamping>0.4</cfmDamping>
  </gazebo>
</robot>
